Workbook

Sheet Raw Data
A1: Element | B1: Method | C1: n | D1: TotalEnergy_Ha | E1: CorrelationEnergy_Ha | F1: Eig1_Ha | G1: Eig2_Ha | H1: Eig3_Ha | I1: Eig4_Ha | J1: Eig5_Ha | K1: Eig6_Ha | L1: Eig7_Ha | M1: Eig8_Ha | N1: Eig9_Ha | O1: Eig10_Ha | P1: Eig11_Ha | Q1: Eig12_Ha | R1: Eig13_Ha | S1: Eig14_Ha | T1: AbsDiff_TotalEnergy_Ha | U1: AbsDiff_CorrelationEnergy_Ha | V1: AbsDiff_Eig1_Ha | W1: AbsDiff_Eig2_Ha | X1: AbsDiff_Eig3_Ha | Y1: AbsDiff_Eig4_Ha | Z1: AbsDiff_Eig5_Ha | AA1: AbsDiff_Eig6_Ha | AB1: AbsDiff_Eig7_Ha | AC1: AbsDiff_Eig8_Ha | AD1: AbsDiff_Eig9_Ha | AE1: AbsDiff_Eig10_Ha | AF1: AbsDiff_Eig11_Ha | AG1: AbsDiff_Eig12_Ha | AH1: AbsDiff_Eig13_Ha | AI1: AbsDiff_Eig14_Ha | AJ1: MaxEigDiff_Ha
A2: He | B2: Midpoint | C2: 5 | D2: -2.9419949 | E2: -0.081498211 | F2: -0.98463768 | T2: =ABS(D2-SUMIFS($D$2:$D$205,$A$2:$A$205,$A2,$B$2:$B$205,$B2,$C$2:$C$205,100)) -> 0.0028055115 | U2: =ABS(E2-SUMIFS($E$2:$E$205,$A$2:$A$205,$A2,$B$2:$B$205,$B2,$C$2:$C$205,100)) -> 0.0017498049 | V2: =IF(ISBLANK(F2),"",ABS(F2-SUMIFS($F$2:$F$205,$A$2:$A$205,$A2,$B$2:$B$205,$B2,$C$2:$C$205,100))) -> 0.083353335 | W2: =IF(ISBLANK(G2),"",ABS(G2-SUMIFS($G$2:$G$205,$A$2:$A$205,$A2,$B$2:$B$205,$B2,$C$2:$C$205,100))) | X2: =IF(ISBLANK(H2),"",ABS(H2-SUMIFS($H$2:$H$205,$A$2:$A$205,$A2,$B$2:$B$205,$B2,$C$2:$C$205,100))) | Y2: =IF(ISBLANK(I2),"",ABS(I2-SUMIFS($I$2:$I$205,$A$2:$A$205,$A2,$B$2:$B$205,$B2,$C$2:$C$205,100))) | Z2: =IF(ISBLANK(J2),"",ABS(J2-SUMIFS($J$2:$J$205,$A$2:$A$205,$A2,$B$2:$B$205,$B2,$C$2:$C$205,100))) | AA2: =IF(ISBLANK(K2),"",ABS(K2-SUMIFS($K$2:$K$205,$A$2:$A$205,$A2,$B$2:$B$205,$B2,$C$2:$C$205,100))) | AB2: =IF(ISBLANK(L2),"",ABS(L2-SUMIFS($L$2:$L$205,$A$2:$A$205,$A2,$B$2:$B$205,$B2,$C$2:$C$205,100))) | AC2: =IF(ISBLANK(M2),"",ABS(M2-SUMIFS($M$2:$M$205,$A$2:$A$205,$A2,$B$2:$B$205,$B2,$C$2:$C$205,100))) | AD2: =IF(ISBLANK(N2),"",ABS(N2-SUMIFS($N$2:$N$205,$A$2:$A$205,$A2,$B$2:$B$205,$B2,$C$2:$C$205,100))) | AE2: =IF(ISBLANK(O2),"",ABS(O2-SUMIFS($O$2:$O$205,$A$2:$A$205,$A2,$B$2:$B$205,$B2,$C$2:$C$205,100))) | AF2: =IF(ISBLANK(P2),"",ABS(P2-SUMIFS($P$2:$P$205,$A$2:$A$205,$A2,$B$2:$B$205,$B2,$C$2:$C$205,100))) | AG2: =IF(ISBLANK(Q2),"",ABS(Q2-SUMIFS($Q$2:$Q$205,$A$2:$A$205,$A2,$B$2:$B$205,$B2,$C$2:$C$205,100))) | AH2: =IF(ISBLANK(R2),"",ABS(R2-SUMIFS($R$2:$R$205,$A$2:$A$205,$A2,$B$2:$B$205,$B2,$C$2:$C$205,100))) | AI2: =IF(ISBLANK(S2),"",ABS(S2-SUMIFS($S$2:$S$205,$A$2:$A$205,$A2,$B$2:$B$205,$B2,$C$2:$C$205,100))) | AJ2: =MAX(V2:AI2) -> 0.083353335
A3: He | B3: Midpoint | C3: 10 | D3: -2.9443114 | E3: -0.082826006 | F3: -1.0002658 | T3: =ABS(D3-SUMIFS($D$2:$D$205,$A$2:$A$205,$A3,$B$2:$B$205,$B3,$C$2:$C$205,100)) -> 0.00048894572 | U3: =ABS(E3-SUMIFS($E$2:$E$205,$A$2:$A$205,$A3,$B$2:$B$205,$B3,$C$2:$C$205,100)) -> 0.00042201019 | V3: =IF(ISBLANK(F3),"",ABS(F3-SUMIFS($F$2:$F$205,$A$2:$A$205,$A3,$B$2:$B$205,$B3,$C$2:$C$205,100))) -> 0.098981459 | W3: =IF(ISBLANK(G3),"",ABS(G3-SUMIFS($G$2:$G$205,$A$2:$A$205,$A3,$B$2:$B$205,$B3,$C$2:$C$205,100))) | X3: =IF(ISBLANK(H3),"",ABS(H3-SUMIFS($H$2:$H$205,$A$2:$A$205,$A3,$B$2:$B$205,$B3,$C$2:$C$205,100))) | Y3: =IF(ISBLANK(I3),"",ABS(I3-SUMIFS($I$2:$I$205,$A$2:$A$205,$A3,$B$2:$B$205,$B3,$C$2:$C$205,100))) | Z3: =IF(ISBLANK(J3),"",ABS(J3-SUMIFS($J$2:$J$205,$A$2:$A$205,$A3,$B$2:$B$205,$B3,$C$2:$C$205,100))) | AA3: =IF(ISBLANK(K3),"",ABS(K3-SUMIFS($K$2:$K$205,$A$2:$A$205,$A3,$B$2:$B$205,$B3,$C$2:$C$205,100))) | AB3: =IF(ISBLANK(L3),"",ABS(L3-SUMIFS($L$2:$L$205,$A$2:$A$205,$A3,$B$2:$B$205,$B3,$C$2:$C$205,100))) | AC3: =IF(ISBLANK(M3),"",ABS(M3-SUMIFS($M$2:$M$205,$A$2:$A$205,$A3,$B$2:$B$205,$B3,$C$2:$C$205,100))) | AD3: =IF(ISBLANK(N3),"",ABS(N3-SUMIFS($N$2:$N$205,$A$2:$A$205,$A3,$B$2:$B$205,$B3,$C$2:$C$205,100))) | AE3: =IF(ISBLANK(O3),"",ABS(O3-SUMIFS($O$2:$O$205,$A$2:$A$205,$A3,$B$2:$B$205,$B3,$C$2:$C$205,100))) | AF3: =IF(ISBLANK(P3),"",ABS(P3-SUMIFS($P$2:$P$205,$A$2:$A$205,$A3,$B$2:$B$205,$B3,$C$2:$C$205,100))) | AG3: =IF(ISBLANK(Q3),"",ABS(Q3-SUMIFS($Q$2:$Q$205,$A$2:$A$205,$A3,$B$2:$B$205,$B3,$C$2:$C$205,100))) | AH3: =IF(ISBLANK(R3),"",ABS(R3-SUMIFS($R$2:$R$205,$A$2:$A$205,$A3,$B$2:$B$205,$B3,$C$2:$C$205,100))) | AI3: =IF(ISBLANK(S3),"",ABS(S3-SUMIFS($S$2:$S$205,$A$2:$A$205,$A3,$B$2:$B$205,$B3,$C$2:$C$205,100))) | AJ3: =MAX(V3:AI3) -> 0.098981459
A4: He | B4: Midpoint | C4: 15 | D4: -2.9446996 | E4: -0.083140016 | F4: -0.98503744 | T4: =ABS(D4-SUMIFS($D$2:$D$205,$A$2:$A$205,$A4,$B$2:$B$205,$B4,$C$2:$C$205,100)) -> 0.00010077465 | U4: =ABS(E4-SUMIFS($E$2:$E$205,$A$2:$A$205,$A4,$B$2:$B$205,$B4,$C$2:$C$205,100)) -> 0.0001080004 | V4: =IF(ISBLANK(F4),"",ABS(F4-SUMIFS($F$2:$F$205,$A$2:$A$205,$A4,$B$2:$B$205,$B4,$C$2:$C$205,100))) -> 0.083753092 | W4: =IF(ISBLANK(G4),"",ABS(G4-SUMIFS($G$2:$G$205,$A$2:$A$205,$A4,$B$2:$B$205,$B4,$C$2:$C$205,100))) | X4: =IF(ISBLANK(H4),"",ABS(H4-SUMIFS($H$2:$H$205,$A$2:$A$205,$A4,$B$2:$B$205,$B4,$C$2:$C$205,100))) | Y4: =IF(ISBLANK(I4),"",ABS(I4-SUMIFS($I$2:$I$205,$A$2:$A$205,$A4,$B$2:$B$205,$B4,$C$2:$C$205,100))) | Z4: =IF(ISBLANK(J4),"",ABS(J4-SUMIFS($J$2:$J$205,$A$2:$A$205,$A4,$B$2:$B$205,$B4,$C$2:$C$205,100))) | AA4: =IF(ISBLANK(K4),"",ABS(K4-SUMIFS($K$2:$K$205,$A$2:$A$205,$A4,$B$2:$B$205,$B4,$C$2:$C$205,100))) | AB4: =IF(ISBLANK(L4),"",ABS(L4-SUMIFS($L$2:$L$205,$A$2:$A$205,$A4,$B$2:$B$205,$B4,$C$2:$C$205,100))) | AC4: =IF(ISBLANK(M4),"",ABS(M4-SUMIFS($M$2:$M$205,$A$2:$A$205,$A4,$B$2:$B$205,$B4,$C$2:$C$205,100))) | AD4: =IF(ISBLANK(N4),"",ABS(N4-SUMIFS($N$2:$N$205,$A$2:$A$205,$A4,$B$2:$B$205,$B4,$C$2:$C$205,100))) | AE4: =IF(ISBLANK(O4),"",ABS(O4-SUMIFS($O$2:$O$205,$A$2:$A$205,$A4,$B$2:$B$205,$B4,$C$2:$C$205,100))) | AF4: =IF(ISBLANK(P4),"",ABS(P4-SUMIFS($P$2:$P$205,$A$2:$A$205,$A4,$B$2:$B$205,$B4,$C$2:$C$205,100))) | AG4: =IF(ISBLANK(Q4),"",ABS(Q4-SUMIFS($Q$2:$Q$205,$A$2:$A$205,$A4,$B$2:$B$205,$B4,$C$2:$C$205,100))) | AH4: =IF(ISBLANK(R4),"",ABS(R4-SUMIFS($R$2:$R$205,$A$2:$A$205,$A4,$B$2:$B$205,$B4,$C$2:$C$205,100))) | AI4: =IF(ISBLANK(S4),"",ABS(S4-SUMIFS($S$2:$S$205,$A$2:$A$205,$A4,$B$2:$B$205,$B4,$C$2:$C$205,100))) | AJ4: =MAX(V4:AI4) -> 0.083753092
A5: He | B5: Midpoint | C5: 20 | D5: -2.9447921 | E5: -0.083237004 | F5: -1.0560708 | T5: =ABS(D5-SUMIFS($D$2:$D$205,$A$2:$A$205,$A5,$B$2:$B$205,$B5,$C$2:$C$205,100)) -> 8.3221154e-06 | U5: =ABS(E5-SUMIFS($E$2:$E$205,$A$2:$A$205,$A5,$B$2:$B$205,$B5,$C$2:$C$205,100)) -> 1.1012191e-05 | V5: =IF(ISBLANK(F5),"",ABS(F5-SUMIFS($F$2:$F$205,$A$2:$A$205,$A5,$B$2:$B$205,$B5,$C$2:$C$205,100))) -> 0.15478642 | W5: =IF(ISBLANK(G5),"",ABS(G5-SUMIFS($G$2:$G$205,$A$2:$A$205,$A5,$B$2:$B$205,$B5,$C$2:$C$205,100))) | X5: =IF(ISBLANK(H5),"",ABS(H5-SUMIFS($H$2:$H$205,$A$2:$A$205,$A5,$B$2:$B$205,$B5,$C$2:$C$205,100))) | Y5: =IF(ISBLANK(I5),"",ABS(I5-SUMIFS($I$2:$I$205,$A$2:$A$205,$A5,$B$2:$B$205,$B5,$C$2:$C$205,100))) | Z5: =IF(ISBLANK(J5),"",ABS(J5-SUMIFS($J$2:$J$205,$A$2:$A$205,$A5,$B$2:$B$205,$B5,$C$2:$C$205,100))) | AA5: =IF(ISBLANK(K5),"",ABS(K5-SUMIFS($K$2:$K$205,$A$2:$A$205,$A5,$B$2:$B$205,$B5,$C$2:$C$205,100))) | AB5: =IF(ISBLANK(L5),"",ABS(L5-SUMIFS($L$2:$L$205,$A$2:$A$205,$A5,$B$2:$B$205,$B5,$C$2:$C$205,100))) | AC5: =IF(ISBLANK(M5),"",ABS(M5-SUMIFS($M$2:$M$205,$A$2:$A$205,$A5,$B$2:$B$205,$B5,$C$2:$C$205,100))) | AD5: =IF(ISBLANK(N5),"",ABS(N5-SUMIFS($N$2:$N$205,$A$2:$A$205,$A5,$B$2:$B$205,$B5,$C$2:$C$205,100))) | AE5: =IF(ISBLANK(O5),"",ABS(O5-SUMIFS($O$2:$O$205,$A$2:$A$205,$A5,$B$2:$B$205,$B5,$C$2:$C$205,100))) | AF5: =IF(ISBLANK(P5),"",ABS(P5-SUMIFS($P$2:$P$205,$A$2:$A$205,$A5,$B$2:$B$205,$B5,$C$2:$C$205,100))) | AG5: =IF(ISBLANK(Q5),"",ABS(Q5-SUMIFS($Q$2:$Q$205,$A$2:$A$205,$A5,$B$2:$B$205,$B5,$C$2:$C$205,100))) | AH5: =IF(ISBLANK(R5),"",ABS(R5-SUMIFS($R$2:$R$205,$A$2:$A$205,$A5,$B$2:$B$205,$B5,$C$2:$C$205,100))) | AI5: =IF(ISBLANK(S5),"",ABS(S5-SUMIFS($S$2:$S$205,$A$2:$A$205,$A5,$B$2:$B$205,$B5,$C$2:$C$205,100))) | AJ5: =MAX(V5:AI5) -> 0.15478642
A6: He | B6: Midpoint | C6: 30 | D6: -2.9448003 | E6: -0.083247938 | F6: -0.99101219 | T6: =ABS(D6-SUMIFS($D$2:$D$205,$A$2:$A$205,$A6,$B$2:$B$205,$B6,$C$2:$C$205,100)) -> 3.4250202e-08 | U6: =ABS(E6-SUMIFS($E$2:$E$205,$A$2:$A$205,$A6,$B$2:$B$205,$B6,$C$2:$C$205,100)) -> 7.8172444e-08 | V6: =IF(ISBLANK(F6),"",ABS(F6-SUMIFS($F$2:$F$205,$A$2:$A$205,$A6,$B$2:$B$205,$B6,$C$2:$C$205,100))) -> 0.089727844 | W6: =IF(ISBLANK(G6),"",ABS(G6-SUMIFS($G$2:$G$205,$A$2:$A$205,$A6,$B$2:$B$205,$B6,$C$2:$C$205,100))) | X6: =IF(ISBLANK(H6),"",ABS(H6-SUMIFS($H$2:$H$205,$A$2:$A$205,$A6,$B$2:$B$205,$B6,$C$2:$C$205,100))) | Y6: =IF(ISBLANK(I6),"",ABS(I6-SUMIFS($I$2:$I$205,$A$2:$A$205,$A6,$B$2:$B$205,$B6,$C$2:$C$205,100))) | Z6: =IF(ISBLANK(J6),"",ABS(J6-SUMIFS($J$2:$J$205,$A$2:$A$205,$A6,$B$2:$B$205,$B6,$C$2:$C$205,100))) | AA6: =IF(ISBLANK(K6),"",ABS(K6-SUMIFS($K$2:$K$205,$A$2:$A$205,$A6,$B$2:$B$205,$B6,$C$2:$C$205,100))) | AB6: =IF(ISBLANK(L6),"",ABS(L6-SUMIFS($L$2:$L$205,$A$2:$A$205,$A6,$B$2:$B$205,$B6,$C$2:$C$205,100))) | AC6: =IF(ISBLANK(M6),"",ABS(M6-SUMIFS($M$2:$M$205,$A$2:$A$205,$A6,$B$2:$B$205,$B6,$C$2:$C$205,100))) | AD6: =IF(ISBLANK(N6),"",ABS(N6-SUMIFS($N$2:$N$205,$A$2:$A$205,$A6,$B$2:$B$205,$B6,$C$2:$C$205,100))) | AE6: =IF(ISBLANK(O6),"",ABS(O6-SUMIFS($O$2:$O$205,$A$2:$A$205,$A6,$B$2:$B$205,$B6,$C$2:$C$205,100))) | AF6: =IF(ISBLANK(P6),"",ABS(P6-SUMIFS($P$2:$P$205,$A$2:$A$205,$A6,$B$2:$B$205,$B6,$C$2:$C$205,100))) | AG6: =IF(ISBLANK(Q6),"",ABS(Q6-SUMIFS($Q$2:$Q$205,$A$2:$A$205,$A6,$B$2:$B$205,$B6,$C$2:$C$205,100))) | AH6: =IF(ISBLANK(R6),"",ABS(R6-SUMIFS($R$2:$R$205,$A$2:$A$205,$A6,$B$2:$B$205,$B6,$C$2:$C$205,100))) | AI6: =IF(ISBLANK(S6),"",ABS(S6-SUMIFS($S$2:$S$205,$A$2:$A$205,$A6,$B$2:$B$205,$B6,$C$2:$C$205,100))) | AJ6: =MAX(V6:AI6) -> 0.089727844
A7: He | B7: Midpoint | C7: 50 | D7: -2.9448004 | E7: -0.083248016 | F7: -0.9012539 | T7: =ABS(D7-SUMIFS($D$2:$D$205,$A$2:$A$205,$A7,$B$2:$B$205,$B7,$C$2:$C$205,100)) -> 8.0069285e-13 | U7: =ABS(E7-SUMIFS($E$2:$E$205,$A$2:$A$205,$A7,$B$2:$B$205,$B7,$C$2:$C$205,100)) -> 3.8424125e-12 | V7: =IF(ISBLANK(F7),"",ABS(F7-SUMIFS($F$2:$F$205,$A$2:$A$205,$A7,$B$2:$B$205,$B7,$C$2:$C$205,100))) -> 3.0444485e-05 | W7: =IF(ISBLANK(G7),"",ABS(G7-SUMIFS($G$2:$G$205,$A$2:$A$205,$A7,$B$2:$B$205,$B7,$C$2:$C$205,100))) | X7: =IF(ISBLANK(H7),"",ABS(H7-SUMIFS($H$2:$H$205,$A$2:$A$205,$A7,$B$2:$B$205,$B7,$C$2:$C$205,100))) | Y7: =IF(ISBLANK(I7),"",ABS(I7-SUMIFS($I$2:$I$205,$A$2:$A$205,$A7,$B$2:$B$205,$B7,$C$2:$C$205,100))) | Z7: =IF(ISBLANK(J7),"",ABS(J7-SUMIFS($J$2:$J$205,$A$2:$A$205,$A7,$B$2:$B$205,$B7,$C$2:$C$205,100))) | AA7: =IF(ISBLANK(K7),"",ABS(K7-SUMIFS($K$2:$K$205,$A$2:$A$205,$A7,$B$2:$B$205,$B7,$C$2:$C$205,100))) | AB7: =IF(ISBLANK(L7),"",ABS(L7-SUMIFS($L$2:$L$205,$A$2:$A$205,$A7,$B$2:$B$205,$B7,$C$2:$C$205,100))) | AC7: =IF(ISBLANK(M7),"",ABS(M7-SUMIFS($M$2:$M$205,$A$2:$A$205,$A7,$B$2:$B$205,$B7,$C$2:$C$205,100))) | AD7: =IF(ISBLANK(N7),"",ABS(N7-SUMIFS($N$2:$N$205,$A$2:$A$205,$A7,$B$2:$B$205,$B7,$C$2:$C$205,100))) | AE7: =IF(ISBLANK(O7),"",ABS(O7-SUMIFS($O$2:$O$205,$A$2:$A$205,$A7,$B$2:$B$205,$B7,$C$2:$C$205,100))) | AF7: =IF(ISBLANK(P7),"",ABS(P7-SUMIFS($P$2:$P$205,$A$2:$A$205,$A7,$B$2:$B$205,$B7,$C$2:$C$205,100))) | AG7: =IF(ISBLANK(Q7),"",ABS(Q7-SUMIFS($Q$2:$Q$205,$A$2:$A$205,$A7,$B$2:$B$205,$B7,$C$2:$C$205,100))) | AH7: =IF(ISBLANK(R7),"",ABS(R7-SUMIFS($R$2:$R$205,$A$2:$A$205,$A7,$B$2:$B$205,$B7,$C$2:$C$205,100))) | AI7: =IF(ISBLANK(S7),"",ABS(S7-SUMIFS($S$2:$S$205,$A$2:$A$205,$A7,$B$2:$B$205,$B7,$C$2:$C$205,100))) | AJ7: =MAX(V7:AI7) -> 3.0444485e-05
A8: He | B8: Midpoint | C8: 80 | D8: -2.9448004 | E8: -0.083248016 | F8: -0.90128435 | T8: =ABS(D8-SUMIFS($D$2:$D$205,$A$2:$A$205,$A8,$B$2:$B$205,$B8,$C$2:$C$205,100)) -> 1.5987212e-14 | U8: =ABS(E8-SUMIFS($E$2:$E$205,$A$2:$A$205,$A8,$B$2:$B$205,$B8,$C$2:$C$205,100)) -> 5.9674488e-15 | V8: =IF(ISBLANK(F8),"",ABS(F8-SUMIFS($F$2:$F$205,$A$2:$A$205,$A8,$B$2:$B$205,$B8,$C$2:$C$205,100))) -> 5.4668714e-10 | W8: =IF(ISBLANK(G8),"",ABS(G8-SUMIFS($G$2:$G$205,$A$2:$A$205,$A8,$B$2:$B$205,$B8,$C$2:$C$205,100))) | X8: =IF(ISBLANK(H8),"",ABS(H8-SUMIFS($H$2:$H$205,$A$2:$A$205,$A8,$B$2:$B$205,$B8,$C$2:$C$205,100))) | Y8: =IF(ISBLANK(I8),"",ABS(I8-SUMIFS($I$2:$I$205,$A$2:$A$205,$A8,$B$2:$B$205,$B8,$C$2:$C$205,100))) | Z8: =IF(ISBLANK(J8),"",ABS(J8-SUMIFS($J$2:$J$205,$A$2:$A$205,$A8,$B$2:$B$205,$B8,$C$2:$C$205,100))) | AA8: =IF(ISBLANK(K8),"",ABS(K8-SUMIFS($K$2:$K$205,$A$2:$A$205,$A8,$B$2:$B$205,$B8,$C$2:$C$205,100))) | AB8: =IF(ISBLANK(L8),"",ABS(L8-SUMIFS($L$2:$L$205,$A$2:$A$205,$A8,$B$2:$B$205,$B8,$C$2:$C$205,100))) | AC8: =IF(ISBLANK(M8),"",ABS(M8-SUMIFS($M$2:$M$205,$A$2:$A$205,$A8,$B$2:$B$205,$B8,$C$2:$C$205,100))) | AD8: =IF(ISBLANK(N8),"",ABS(N8-SUMIFS($N$2:$N$205,$A$2:$A$205,$A8,$B$2:$B$205,$B8,$C$2:$C$205,100))) | AE8: =IF(ISBLANK(O8),"",ABS(O8-SUMIFS($O$2:$O$205,$A$2:$A$205,$A8,$B$2:$B$205,$B8,$C$2:$C$205,100))) | AF8: =IF(ISBLANK(P8),"",ABS(P8-SUMIFS($P$2:$P$205,$A$2:$A$205,$A8,$B$2:$B$205,$B8,$C$2:$C$205,100))) | AG8: =IF(ISBLANK(Q8),"",ABS(Q8-SUMIFS($Q$2:$Q$205,$A$2:$A$205,$A8,$B$2:$B$205,$B8,$C$2:$C$205,100))) | AH8: =IF(ISBLANK(R8),"",ABS(R8-SUMIFS($R$2:$R$205,$A$2:$A$205,$A8,$B$2:$B$205,$B8,$C$2:$C$205,100))) | AI8: =IF(ISBLANK(S8),"",ABS(S8-SUMIFS($S$2:$S$205,$A$2:$A$205,$A8,$B$2:$B$205,$B8,$C$2:$C$205,100))) | AJ8: =MAX(V8:AI8) -> 5.4668714e-10
A9: He | B9: Midpoint | C9: 100 | D9: -2.9448004 | E9: -0.083248016 | F9: -0.90128435 | T9: =ABS(D9-SUMIFS($D$2:$D$205,$A$2:$A$205,$A9,$B$2:$B$205,$B9,$C$2:$C$205,100)) -> 0 | U9: =ABS(E9-SUMIFS($E$2:$E$205,$A$2:$A$205,$A9,$B$2:$B$205,$B9,$C$2:$C$205,100)) -> 0 | V9: =IF(ISBLANK(F9),"",ABS(F9-SUMIFS($F$2:$F$205,$A$2:$A$205,$A9,$B$2:$B$205,$B9,$C$2:$C$205,100))) -> 0 | W9: =IF(ISBLANK(G9),"",ABS(G9-SUMIFS($G$2:$G$205,$A$2:$A$205,$A9,$B$2:$B$205,$B9,$C$2:$C$205,100))) | X9: =IF(ISBLANK(H9),"",ABS(H9-SUMIFS($H$2:$H$205,$A$2:$A$205,$A9,$B$2:$B$205,$B9,$C$2:$C$205,100))) | Y9: =IF(ISBLANK(I9),"",ABS(I9-SUMIFS($I$2:$I$205,$A$2:$A$205,$A9,$B$2:$B$205,$B9,$C$2:$C$205,100))) | Z9: =IF(ISBLANK(J9),"",ABS(J9-SUMIFS($J$2:$J$205,$A$2:$A$205,$A9,$B$2:$B$205,$B9,$C$2:$C$205,100))) | AA9: =IF(ISBLANK(K9),"",ABS(K9-SUMIFS($K$2:$K$205,$A$2:$A$205,$A9,$B$2:$B$205,$B9,$C$2:$C$205,100))) | AB9: =IF(ISBLANK(L9),"",ABS(L9-SUMIFS($L$2:$L$205,$A$2:$A$205,$A9,$B$2:$B$205,$B9,$C$2:$C$205,100))) | AC9: =IF(ISBLANK(M9),"",ABS(M9-SUMIFS($M$2:$M$205,$A$2:$A$205,$A9,$B$2:$B$205,$B9,$C$2:$C$205,100))) | AD9: =IF(ISBLANK(N9),"",ABS(N9-SUMIFS($N$2:$N$205,$A$2:$A$205,$A9,$B$2:$B$205,$B9,$C$2:$C$205,100))) | AE9: =IF(ISBLANK(O9),"",ABS(O9-SUMIFS($O$2:$O$205,$A$2:$A$205,$A9,$B$2:$B$205,$B9,$C$2:$C$205,100))) | AF9: =IF(ISBLANK(P9),"",ABS(P9-SUMIFS($P$2:$P$205,$A$2:$A$205,$A9,$B$2:$B$205,$B9,$C$2:$C$205,100))) | AG9: =IF(ISBLANK(Q9),"",ABS(Q9-SUMIFS($Q$2:$Q$205,$A$2:$A$205,$A9,$B$2:$B$205,$B9,$C$2:$C$205,100))) | AH9: =IF(ISBLANK(R9),"",ABS(R9-SUMIFS($R$2:$R$205,$A$2:$A$205,$A9,$B$2:$B$205,$B9,$C$2:$C$205,100))) | AI9: =IF(ISBLANK(S9),"",ABS(S9-SUMIFS($S$2:$S$205,$A$2:$A$205,$A9,$B$2:$B$205,$B9,$C$2:$C$205,100))) | AJ9: =MAX(V9:AI9) -> 0
A10: He | B10: Trapezoidal | C10: 5 | D10: 28524.887 | E10: -0.41943629 | F10: -2.0668795e+13 | T10: =ABS(D10-SUMIFS($D$2:$D$205,$A$2:$A$205,$A10,$B$2:$B$205,$B10,$C$2:$C$205,100)) -> 28527.832 | U10: =ABS(E10-SUMIFS($E$2:$E$205,$A$2:$A$205,$A10,$B$2:$B$205,$B10,$C$2:$C$205,100)) -> 0.33618827 | V10: =IF(ISBLANK(F10),"",ABS(F10-SUMIFS($F$2:$F$205,$A$2:$A$205,$A10,$B$2:$B$205,$B10,$C$2:$C$205,100))) -> 2.0668795e+13 | W10: =IF(ISBLANK(G10),"",ABS(G10-SUMIFS($G$2:$G$205,$A$2:$A$205,$A10,$B$2:$B$205,$B10,$C$2:$C$205,100))) | X10: =IF(ISBLANK(H10),"",ABS(H10-SUMIFS($H$2:$H$205,$A$2:$A$205,$A10,$B$2:$B$205,$B10,$C$2:$C$205,100))) | Y10: =IF(ISBLANK(I10),"",ABS(I10-SUMIFS($I$2:$I$205,$A$2:$A$205,$A10,$B$2:$B$205,$B10,$C$2:$C$205,100))) | Z10: =IF(ISBLANK(J10),"",ABS(J10-SUMIFS($J$2:$J$205,$A$2:$A$205,$A10,$B$2:$B$205,$B10,$C$2:$C$205,100))) | AA10: =IF(ISBLANK(K10),"",ABS(K10-SUMIFS($K$2:$K$205,$A$2:$A$205,$A10,$B$2:$B$205,$B10,$C$2:$C$205,100))) | AB10: =IF(ISBLANK(L10),"",ABS(L10-SUMIFS($L$2:$L$205,$A$2:$A$205,$A10,$B$2:$B$205,$B10,$C$2:$C$205,100))) | AC10: =IF(ISBLANK(M10),"",ABS(M10-SUMIFS($M$2:$M$205,$A$2:$A$205,$A10,$B$2:$B$205,$B10,$C$2:$C$205,100))) | AD10: =IF(ISBLANK(N10),"",ABS(N10-SUMIFS($N$2:$N$205,$A$2:$A$205,$A10,$B$2:$B$205,$B10,$C$2:$C$205,100))) | AE10: =IF(ISBLANK(O10),"",ABS(O10-SUMIFS($O$2:$O$205,$A$2:$A$205,$A10,$B$2:$B$205,$B10,$C$2:$C$205,100))) | AF10: =IF(ISBLANK(P10),"",ABS(P10-SUMIFS($P$2:$P$205,$A$2:$A$205,$A10,$B$2:$B$205,$B10,$C$2:$C$205,100))) | AG10: =IF(ISBLANK(Q10),"",ABS(Q10-SUMIFS($Q$2:$Q$205,$A$2:$A$205,$A10,$B$2:$B$205,$B10,$C$2:$C$205,100))) | AH10: =IF(ISBLANK(R10),"",ABS(R10-SUMIFS($R$2:$R$205,$A$2:$A$205,$A10,$B$2:$B$205,$B10,$C$2:$C$205,100))) | AI10: =IF(ISBLANK(S10),"",ABS(S10-SUMIFS($S$2:$S$205,$A$2:$A$205,$A10,$B$2:$B$205,$B10,$C$2:$C$205,100))) | AJ10: =MAX(V10:AI10) -> 2.0668795e+13
A11: He | B11: Trapezoidal | C11: 10 | D11: -2.9439203 | E11: -0.082453201 | F11: -0.51030552 | T11: =ABS(D11-SUMIFS($D$2:$D$205,$A$2:$A$205,$A11,$B$2:$B$205,$B11,$C$2:$C$205,100)) -> 0.00088005594 | U11: =ABS(E11-SUMIFS($E$2:$E$205,$A$2:$A$205,$A11,$B$2:$B$205,$B11,$C$2:$C$205,100)) -> 0.00079481501 | V11: =IF(ISBLANK(F11),"",ABS(F11-SUMIFS($F$2:$F$205,$A$2:$A$205,$A11,$B$2:$B$205,$B11,$C$2:$C$205,100))) -> 0.39097882 | W11: =IF(ISBLANK(G11),"",ABS(G11-SUMIFS($G$2:$G$205,$A$2:$A$205,$A11,$B$2:$B$205,$B11,$C$2:$C$205,100))) | X11: =IF(ISBLANK(H11),"",ABS(H11-SUMIFS($H$2:$H$205,$A$2:$A$205,$A11,$B$2:$B$205,$B11,$C$2:$C$205,100))) | Y11: =IF(ISBLANK(I11),"",ABS(I11-SUMIFS($I$2:$I$205,$A$2:$A$205,$A11,$B$2:$B$205,$B11,$C$2:$C$205,100))) | Z11: =IF(ISBLANK(J11),"",ABS(J11-SUMIFS($J$2:$J$205,$A$2:$A$205,$A11,$B$2:$B$205,$B11,$C$2:$C$205,100))) | AA11: =IF(ISBLANK(K11),"",ABS(K11-SUMIFS($K$2:$K$205,$A$2:$A$205,$A11,$B$2:$B$205,$B11,$C$2:$C$205,100))) | AB11: =IF(ISBLANK(L11),"",ABS(L11-SUMIFS($L$2:$L$205,$A$2:$A$205,$A11,$B$2:$B$205,$B11,$C$2:$C$205,100))) | AC11: =IF(ISBLANK(M11),"",ABS(M11-SUMIFS($M$2:$M$205,$A$2:$A$205,$A11,$B$2:$B$205,$B11,$C$2:$C$205,100))) | AD11: =IF(ISBLANK(N11),"",ABS(N11-SUMIFS($N$2:$N$205,$A$2:$A$205,$A11,$B$2:$B$205,$B11,$C$2:$C$205,100))) | AE11: =IF(ISBLANK(O11),"",ABS(O11-SUMIFS($O$2:$O$205,$A$2:$A$205,$A11,$B$2:$B$205,$B11,$C$2:$C$205,100))) | AF11: =IF(ISBLANK(P11),"",ABS(P11-SUMIFS($P$2:$P$205,$A$2:$A$205,$A11,$B$2:$B$205,$B11,$C$2:$C$205,100))) | AG11: =IF(ISBLANK(Q11),"",ABS(Q11-SUMIFS($Q$2:$Q$205,$A$2:$A$205,$A11,$B$2:$B$205,$B11,$C$2:$C$205,100))) | AH11: =IF(ISBLANK(R11),"",ABS(R11-SUMIFS($R$2:$R$205,$A$2:$A$205,$A11,$B$2:$B$205,$B11,$C$2:$C$205,100))) | AI11: =IF(ISBLANK(S11),"",ABS(S11-SUMIFS($S$2:$S$205,$A$2:$A$205,$A11,$B$2:$B$205,$B11,$C$2:$C$205,100))) | AJ11: =MAX(V11:AI11) -> 0.39097882
A12: He | B12: Trapezoidal | C12: 15 | D12: -2.9447731 | E12: -0.083226639 | F12: -0.64457755 | T12: =ABS(D12-SUMIFS($D$2:$D$205,$A$2:$A$205,$A12,$B$2:$B$205,$B12,$C$2:$C$205,100)) -> 2.728028e-05 | U12: =ABS(E12-SUMIFS($E$2:$E$205,$A$2:$A$205,$A12,$B$2:$B$205,$B12,$C$2:$C$205,100)) -> 2.1377196e-05 | V12: =IF(ISBLANK(F12),"",ABS(F12-SUMIFS($F$2:$F$205,$A$2:$A$205,$A12,$B$2:$B$205,$B12,$C$2:$C$205,100))) -> 0.25670679 | W12: =IF(ISBLANK(G12),"",ABS(G12-SUMIFS($G$2:$G$205,$A$2:$A$205,$A12,$B$2:$B$205,$B12,$C$2:$C$205,100))) | X12: =IF(ISBLANK(H12),"",ABS(H12-SUMIFS($H$2:$H$205,$A$2:$A$205,$A12,$B$2:$B$205,$B12,$C$2:$C$205,100))) | Y12: =IF(ISBLANK(I12),"",ABS(I12-SUMIFS($I$2:$I$205,$A$2:$A$205,$A12,$B$2:$B$205,$B12,$C$2:$C$205,100))) | Z12: =IF(ISBLANK(J12),"",ABS(J12-SUMIFS($J$2:$J$205,$A$2:$A$205,$A12,$B$2:$B$205,$B12,$C$2:$C$205,100))) | AA12: =IF(ISBLANK(K12),"",ABS(K12-SUMIFS($K$2:$K$205,$A$2:$A$205,$A12,$B$2:$B$205,$B12,$C$2:$C$205,100))) | AB12: =IF(ISBLANK(L12),"",ABS(L12-SUMIFS($L$2:$L$205,$A$2:$A$205,$A12,$B$2:$B$205,$B12,$C$2:$C$205,100))) | AC12: =IF(ISBLANK(M12),"",ABS(M12-SUMIFS($M$2:$M$205,$A$2:$A$205,$A12,$B$2:$B$205,$B12,$C$2:$C$205,100))) | AD12: =IF(ISBLANK(N12),"",ABS(N12-SUMIFS($N$2:$N$205,$A$2:$A$205,$A12,$B$2:$B$205,$B12,$C$2:$C$205,100))) | AE12: =IF(ISBLANK(O12),"",ABS(O12-SUMIFS($O$2:$O$205,$A$2:$A$205,$A12,$B$2:$B$205,$B12,$C$2:$C$205,100))) | AF12: =IF(ISBLANK(P12),"",ABS(P12-SUMIFS($P$2:$P$205,$A$2:$A$205,$A12,$B$2:$B$205,$B12,$C$2:$C$205,100))) | AG12: =IF(ISBLANK(Q12),"",ABS(Q12-SUMIFS($Q$2:$Q$205,$A$2:$A$205,$A12,$B$2:$B$205,$B12,$C$2:$C$205,100))) | AH12: =IF(ISBLANK(R12),"",ABS(R12-SUMIFS($R$2:$R$205,$A$2:$A$205,$A12,$B$2:$B$205,$B12,$C$2:$C$205,100))) | AI12: =IF(ISBLANK(S12),"",ABS(S12-SUMIFS($S$2:$S$205,$A$2:$A$205,$A12,$B$2:$B$205,$B12,$C$2:$C$205,100))) | AJ12: =MAX(V12:AI12) -> 0.25670679
A13: He | B13: Trapezoidal | C13: 20 | D13: -2.9447981 | E13: -0.083246697 | F13: -0.72407427 | T13: =ABS(D13-SUMIFS($D$2:$D$205,$A$2:$A$205,$A13,$B$2:$B$205,$B13,$C$2:$C$205,100)) -> 2.3026183e-06 | U13: =ABS(E13-SUMIFS($E$2:$E$205,$A$2:$A$205,$A13,$B$2:$B$205,$B13,$C$2:$C$205,100)) -> 1.3193778e-06 | V13: =IF(ISBLANK(F13),"",ABS(F13-SUMIFS($F$2:$F$205,$A$2:$A$205,$A13,$B$2:$B$205,$B13,$C$2:$C$205,100))) -> 0.17721008 | W13: =IF(ISBLANK(G13),"",ABS(G13-SUMIFS($G$2:$G$205,$A$2:$A$205,$A13,$B$2:$B$205,$B13,$C$2:$C$205,100))) | X13: =IF(ISBLANK(H13),"",ABS(H13-SUMIFS($H$2:$H$205,$A$2:$A$205,$A13,$B$2:$B$205,$B13,$C$2:$C$205,100))) | Y13: =IF(ISBLANK(I13),"",ABS(I13-SUMIFS($I$2:$I$205,$A$2:$A$205,$A13,$B$2:$B$205,$B13,$C$2:$C$205,100))) | Z13: =IF(ISBLANK(J13),"",ABS(J13-SUMIFS($J$2:$J$205,$A$2:$A$205,$A13,$B$2:$B$205,$B13,$C$2:$C$205,100))) | AA13: =IF(ISBLANK(K13),"",ABS(K13-SUMIFS($K$2:$K$205,$A$2:$A$205,$A13,$B$2:$B$205,$B13,$C$2:$C$205,100))) | AB13: =IF(ISBLANK(L13),"",ABS(L13-SUMIFS($L$2:$L$205,$A$2:$A$205,$A13,$B$2:$B$205,$B13,$C$2:$C$205,100))) | AC13: =IF(ISBLANK(M13),"",ABS(M13-SUMIFS($M$2:$M$205,$A$2:$A$205,$A13,$B$2:$B$205,$B13,$C$2:$C$205,100))) | AD13: =IF(ISBLANK(N13),"",ABS(N13-SUMIFS($N$2:$N$205,$A$2:$A$205,$A13,$B$2:$B$205,$B13,$C$2:$C$205,100))) | AE13: =IF(ISBLANK(O13),"",ABS(O13-SUMIFS($O$2:$O$205,$A$2:$A$205,$A13,$B$2:$B$205,$B13,$C$2:$C$205,100))) | AF13: =IF(ISBLANK(P13),"",ABS(P13-SUMIFS($P$2:$P$205,$A$2:$A$205,$A13,$B$2:$B$205,$B13,$C$2:$C$205,100))) | AG13: =IF(ISBLANK(Q13),"",ABS(Q13-SUMIFS($Q$2:$Q$205,$A$2:$A$205,$A13,$B$2:$B$205,$B13,$C$2:$C$205,100))) | AH13: =IF(ISBLANK(R13),"",ABS(R13-SUMIFS($R$2:$R$205,$A$2:$A$205,$A13,$B$2:$B$205,$B13,$C$2:$C$205,100))) | AI13: =IF(ISBLANK(S13),"",ABS(S13-SUMIFS($S$2:$S$205,$A$2:$A$205,$A13,$B$2:$B$205,$B13,$C$2:$C$205,100))) | AJ13: =MAX(V13:AI13) -> 0.17721008
... A41: He | B41: Algebraic | C41: 100 | D41: -2.9448004 | E41: -0.083248013 | F41: -0.90128434 | T41: =ABS(D41-SUMIFS($D$2:$D$205,$A$2:$A$205,$A41,$B$2:$B$205,$B41,$C$2:$C$205,100)) -> 0 | U41: =ABS(E41-SUMIFS($E$2:$E$205,$A$2:$A$205,$A41,$B$2:$B$205,$B41,$C$2:$C$205,100)) -> 0 | V41: =IF(ISBLANK(F41),"",ABS(F41-SUMIFS($F$2:$F$205,$A$2:$A$205,$A41,$B$2:$B$205,$B41,$C$2:$C$205,100))) -> 0 | W41: =IF(ISBLANK(G41),"",ABS(G41-SUMIFS($G$2:$G$205,$A$2:$A$205,$A41,$B$2:$B$205,$B41,$C$2:$C$205,100))) | X41: =IF(ISBLANK(H41),"",ABS(H41-SUMIFS($H$2:$H$205,$A$2:$A$205,$A41,$B$2:$B$205,$B41,$C$2:$C$205,100))) | Y41: =IF(ISBLANK(I41),"",ABS(I41-SUMIFS($I$2:$I$205,$A$2:$A$205,$A41,$B$2:$B$205,$B41,$C$2:$C$205,100))) | Z41: =IF(ISBLANK(J41),"",ABS(J41-SUMIFS($J$2:$J$205,$A$2:$A$205,$A41,$B$2:$B$205,$B41,$C$2:$C$205,100))) | AA41: =IF(ISBLANK(K41),"",ABS(K41-SUMIFS($K$2:$K$205,$A$2:$A$205,$A41,$B$2:$B$205,$B41,$C$2:$C$205,100))) | AB41: =IF(ISBLANK(L41),"",ABS(L41-SUMIFS($L$2:$L$205,$A$2:$A$205,$A41,$B$2:$B$205,$B41,$C$2:$C$205,100))) | AC41: =IF(ISBLANK(M41),"",ABS(M41-SUMIFS($M$2:$M$205,$A$2:$A$205,$A41,$B$2:$B$205,$B41,$C$2:$C$205,100))) | AD41: =IF(ISBLANK(N41),"",ABS(N41-SUMIFS($N$2:$N$205,$A$2:$A$205,$A41,$B$2:$B$205,$B41,$C$2:$C$205,100))) | AE41: =IF(ISBLANK(O41),"",ABS(O41-SUMIFS($O$2:$O$205,$A$2:$A$205,$A41,$B$2:$B$205,$B41,$C$2:$C$205,100))) | AF41: =IF(ISBLANK(P41),"",ABS(P41-SUMIFS($P$2:$P$205,$A$2:$A$205,$A41,$B$2:$B$205,$B41,$C$2:$C$205,100))) | AG41: =IF(ISBLANK(Q41),"",ABS(Q41-SUMIFS($Q$2:$Q$205,$A$2:$A$205,$A41,$B$2:$B$205,$B41,$C$2:$C$205,100))) | AH41: =IF(ISBLANK(R41),"",ABS(R41-SUMIFS($R$2:$R$205,$A$2:$A$205,$A41,$B$2:$B$205,$B41,$C$2:$C$205,100))) | AI41: =IF(ISBLANK(S41),"",ABS(S41-SUMIFS($S$2:$S$205,$A$2:$A$205,$A41,$B$2:$B$205,$B41,$C$2:$C$205,100))) | AJ41: =MAX(V41:AI41) -> 0
A42: Ar | B42: Midpoint | C42: 5 | D42: -527.74246 | E42: -0.93519083 | F42: -114.44878 | G42: -11.120646 | H42: -8.7148367 | I42: -1.1612213 | J42: -0.64846582 | T42: =ABS(D42-SUMIFS($D$2:$D$205,$A$2:$A$205,$A42,$B$2:$B$205,$B42,$C$2:$C$205,100)) -> 0.14194154 | U42: =ABS(E42-SUMIFS($E$2:$E$205,$A$2:$A$205,$A42,$B$2:$B$205,$B42,$C$2:$C$205,100)) -> 0.13864904 | V42: =IF(ISBLANK(F42),"",ABS(F42-SUMIFS($F$2:$F$205,$A$2:$A$205,$A42,$B$2:$B$205,$B42,$C$2:$C$205,100))) -> 0.025750001 | W42: =IF(ISBLANK(G42),"",ABS(G42-SUMIFS($G$2:$G$205,$A$2:$A$205,$A42,$B$2:$B$205,$B42,$C$2:$C$205,100))) -> 0.030731474 | X42: =IF(ISBLANK(H42),"",ABS(H42-SUMIFS($H$2:$H$205,$A$2:$A$205,$A42,$B$2:$B$205,$B42,$C$2:$C$205,100))) -> 0.021186975 | Y42: =IF(ISBLANK(I42),"",ABS(I42-SUMIFS($I$2:$I$205,$A$2:$A$205,$A42,$B$2:$B$205,$B42,$C$2:$C$205,100))) -> 0.065589215 | Z42: =IF(ISBLANK(J42),"",ABS(J42-SUMIFS($J$2:$J$205,$A$2:$A$205,$A42,$B$2:$B$205,$B42,$C$2:$C$205,100))) -> 0.062574213 | AA42: =IF(ISBLANK(K42),"",ABS(K42-SUMIFS($K$2:$K$205,$A$2:$A$205,$A42,$B$2:$B$205,$B42,$C$2:$C$205,100))) | AB42: =IF(ISBLANK(L42),"",ABS(L42-SUMIFS($L$2:$L$205,$A$2:$A$205,$A42,$B$2:$B$205,$B42,$C$2:$C$205,100))) | AC42: =IF(ISBLANK(M42),"",ABS(M42-SUMIFS($M$2:$M$205,$A$2:$A$205,$A42,$B$2:$B$205,$B42,$C$2:$C$205,100))) | AD42: =IF(ISBLANK(N42),"",ABS(N42-SUMIFS($N$2:$N$205,$A$2:$A$205,$A42,$B$2:$B$205,$B42,$C$2:$C$205,100))) | AE42: =IF(ISBLANK(O42),"",ABS(O42-SUMIFS($O$2:$O$205,$A$2:$A$205,$A42,$B$2:$B$205,$B42,$C$2:$C$205,100))) | AF42: =IF(ISBLANK(P42),"",ABS(P42-SUMIFS($P$2:$P$205,$A$2:$A$205,$A42,$B$2:$B$205,$B42,$C$2:$C$205,100))) | AG42: =IF(ISBLANK(Q42),"",ABS(Q42-SUMIFS($Q$2:$Q$205,$A$2:$A$205,$A42,$B$2:$B$205,$B42,$C$2:$C$205,100))) | AH42: =IF(ISBLANK(R42),"",ABS(R42-SUMIFS($R$2:$R$205,$A$2:$A$205,$A42,$B$2:$B$205,$B42,$C$2:$C$205,100))) | AI42: =IF(ISBLANK(S42),"",ABS(S42-SUMIFS($S$2:$S$205,$A$2:$A$205,$A42,$B$2:$B$205,$B42,$C$2:$C$205,100))) | AJ42: =MAX(V42:AI42) -> 0.065589215
A43: Ar | B43: Midpoint | C43: 10 | D43: -527.88127 | E43: -1.0711692 | F43: -114.52265 | G43: -11.19542 | H43: -8.7808886 | I43: -1.153362 | J43: -0.64311047 | T43: =ABS(D43-SUMIFS($D$2:$D$205,$A$2:$A$205,$A43,$B$2:$B$205,$B43,$C$2:$C$205,100)) -> 0.0031362855 | U43: =ABS(E43-SUMIFS($E$2:$E$205,$A$2:$A$205,$A43,$B$2:$B$205,$B43,$C$2:$C$205,100)) -> 0.0026707077 | V43: =IF(ISBLANK(F43),"",ABS(F43-SUMIFS($F$2:$F$205,$A$2:$A$205,$A43,$B$2:$B$205,$B43,$C$2:$C$205,100))) -> 0.048111738 | W43: =IF(ISBLANK(G43),"",ABS(G43-SUMIFS($G$2:$G$205,$A$2:$A$205,$A43,$B$2:$B$205,$B43,$C$2:$C$205,100))) -> 0.044043239 | X43: =IF(ISBLANK(H43),"",ABS(H43-SUMIFS($H$2:$H$205,$A$2:$A$205,$A43,$B$2:$B$205,$B43,$C$2:$C$205,100))) -> 0.044864843 | Y43: =IF(ISBLANK(I43),"",ABS(I43-SUMIFS($I$2:$I$205,$A$2:$A$205,$A43,$B$2:$B$205,$B43,$C$2:$C$205,100))) -> 0.057729953 | Z43: =IF(ISBLANK(J43),"",ABS(J43-SUMIFS($J$2:$J$205,$A$2:$A$205,$A43,$B$2:$B$205,$B43,$C$2:$C$205,100))) -> 0.057218856 | AA43: =IF(ISBLANK(K43),"",ABS(K43-SUMIFS($K$2:$K$205,$A$2:$A$205,$A43,$B$2:$B$205,$B43,$C$2:$C$205,100))) | AB43: =IF(ISBLANK(L43),"",ABS(L43-SUMIFS($L$2:$L$205,$A$2:$A$205,$A43,$B$2:$B$205,$B43,$C$2:$C$205,100))) | AC43: =IF(ISBLANK(M43),"",ABS(M43-SUMIFS($M$2:$M$205,$A$2:$A$205,$A43,$B$2:$B$205,$B43,$C$2:$C$205,100))) | AD43: =IF(ISBLANK(N43),"",ABS(N43-SUMIFS($N$2:$N$205,$A$2:$A$205,$A43,$B$2:$B$205,$B43,$C$2:$C$205,100))) | AE43: =IF(ISBLANK(O43),"",ABS(O43-SUMIFS($O$2:$O$205,$A$2:$A$205,$A43,$B$2:$B$205,$B43,$C$2:$C$205,100))) | AF43: =IF(ISBLANK(P43),"",ABS(P43-SUMIFS($P$2:$P$205,$A$2:$A$205,$A43,$B$2:$B$205,$B43,$C$2:$C$205,100))) | AG43: =IF(ISBLANK(Q43),"",ABS(Q43-SUMIFS($Q$2:$Q$205,$A$2:$A$205,$A43,$B$2:$B$205,$B43,$C$2:$C$205,100))) | AH43: =IF(ISBLANK(R43),"",ABS(R43-SUMIFS($R$2:$R$205,$A$2:$A$205,$A43,$B$2:$B$205,$B43,$C$2:$C$205,100))) | AI43: =IF(ISBLANK(S43),"",ABS(S43-SUMIFS($S$2:$S$205,$A$2:$A$205,$A43,$B$2:$B$205,$B43,$C$2:$C$205,100))) | AJ43: =MAX(V43:AI43) -> 0.057729953
A44: Ar | B44: Midpoint | C44: 15 | D44: -527.88416 | E44: -1.0736067 | F44: -114.57536 | G44: -11.252555 | H44: -8.8371075 | I44: -1.1981351 | J44: -0.68841577 | T44: =ABS(D44-SUMIFS($D$2:$D$205,$A$2:$A$205,$A44,$B$2:$B$205,$B44,$C$2:$C$205,100)) -> 0.00024118199 | U44: =ABS(E44-SUMIFS($E$2:$E$205,$A$2:$A$205,$A44,$B$2:$B$205,$B44,$C$2:$C$205,100)) -> 0.00023314907 | V44: =IF(ISBLANK(F44),"",ABS(F44-SUMIFS($F$2:$F$205,$A$2:$A$205,$A44,$B$2:$B$205,$B44,$C$2:$C$205,100))) -> 0.10082138 | W44: =IF(ISBLANK(G44),"",ABS(G44-SUMIFS($G$2:$G$205,$A$2:$A$205,$A44,$B$2:$B$205,$B44,$C$2:$C$205,100))) -> 0.10117818 | X44: =IF(ISBLANK(H44),"",ABS(H44-SUMIFS($H$2:$H$205,$A$2:$A$205,$A44,$B$2:$B$205,$B44,$C$2:$C$205,100))) -> 0.10108379 | Y44: =IF(ISBLANK(I44),"",ABS(I44-SUMIFS($I$2:$I$205,$A$2:$A$205,$A44,$B$2:$B$205,$B44,$C$2:$C$205,100))) -> 0.10250298 | Z44: =IF(ISBLANK(J44),"",ABS(J44-SUMIFS($J$2:$J$205,$A$2:$A$205,$A44,$B$2:$B$205,$B44,$C$2:$C$205,100))) -> 0.10252416 | AA44: =IF(ISBLANK(K44),"",ABS(K44-SUMIFS($K$2:$K$205,$A$2:$A$205,$A44,$B$2:$B$205,$B44,$C$2:$C$205,100))) | AB44: =IF(ISBLANK(L44),"",ABS(L44-SUMIFS($L$2:$L$205,$A$2:$A$205,$A44,$B$2:$B$205,$B44,$C$2:$C$205,100))) | AC44: =IF(ISBLANK(M44),"",ABS(M44-SUMIFS($M$2:$M$205,$A$2:$A$205,$A44,$B$2:$B$205,$B44,$C$2:$C$205,100))) | AD44: =IF(ISBLANK(N44),"",ABS(N44-SUMIFS($N$2:$N$205,$A$2:$A$205,$A44,$B$2:$B$205,$B44,$C$2:$C$205,100))) | AE44: =IF(ISBLANK(O44),"",ABS(O44-SUMIFS($O$2:$O$205,$A$2:$A$205,$A44,$B$2:$B$205,$B44,$C$2:$C$205,100))) | AF44: =IF(ISBLANK(P44),"",ABS(P44-SUMIFS($P$2:$P$205,$A$2:$A$205,$A44,$B$2:$B$205,$B44,$C$2:$C$205,100))) | AG44: =IF(ISBLANK(Q44),"",ABS(Q44-SUMIFS($Q$2:$Q$205,$A$2:$A$205,$A44,$B$2:$B$205,$B44,$C$2:$C$205,100))) | AH44: =IF(ISBLANK(R44),"",ABS(R44-SUMIFS($R$2:$R$205,$A$2:$A$205,$A44,$B$2:$B$205,$B44,$C$2:$C$205,100))) | AI44: =IF(ISBLANK(S44),"",ABS(S44-SUMIFS($S$2:$S$205,$A$2:$A$205,$A44,$B$2:$B$205,$B44,$C$2:$C$205,100))) | AJ44: =MAX(V44:AI44) -> 0.10252416
A45: Ar | B45: Midpoint | C45: 20 | D45: -527.88438 | E45: -1.0738187 | F45: -114.54465 | G45: -11.221432 | H45: -8.8060837 | I45: -1.1658284 | J45: -0.6560938 | T45: =ABS(D45-SUMIFS($D$2:$D$205,$A$2:$A$205,$A45,$B$2:$B$205,$B45,$C$2:$C$205,100)) -> 2.2364385e-05 | U45: =ABS(E45-SUMIFS($E$2:$E$205,$A$2:$A$205,$A45,$B$2:$B$205,$B45,$C$2:$C$205,100)) -> 2.1128332e-05 | V45: =IF(ISBLANK(F45),"",ABS(F45-SUMIFS($F$2:$F$205,$A$2:$A$205,$A45,$B$2:$B$205,$B45,$C$2:$C$205,100))) -> 0.070117271 | W45: =IF(ISBLANK(G45),"",ABS(G45-SUMIFS($G$2:$G$205,$A$2:$A$205,$A45,$B$2:$B$205,$B45,$C$2:$C$205,100))) -> 0.070054753 | X45: =IF(ISBLANK(H45),"",ABS(H45-SUMIFS($H$2:$H$205,$A$2:$A$205,$A45,$B$2:$B$205,$B45,$C$2:$C$205,100))) -> 0.07005994 | Y45: =IF(ISBLANK(I45),"",ABS(I45-SUMIFS($I$2:$I$205,$A$2:$A$205,$A45,$B$2:$B$205,$B45,$C$2:$C$205,100))) -> 0.070196284 | Z45: =IF(ISBLANK(J45),"",ABS(J45-SUMIFS($J$2:$J$205,$A$2:$A$205,$A45,$B$2:$B$205,$B45,$C$2:$C$205,100))) -> 0.070202189 | AA45: =IF(ISBLANK(K45),"",ABS(K45-SUMIFS($K$2:$K$205,$A$2:$A$205,$A45,$B$2:$B$205,$B45,$C$2:$C$205,100))) | AB45: =IF(ISBLANK(L45),"",ABS(L45-SUMIFS($L$2:$L$205,$A$2:$A$205,$A45,$B$2:$B$205,$B45,$C$2:$C$205,100))) | AC45: =IF(ISBLANK(M45),"",ABS(M45-SUMIFS($M$2:$M$205,$A$2:$A$205,$A45,$B$2:$B$205,$B45,$C$2:$C$205,100))) | AD45: =IF(ISBLANK(N45),"",ABS(N45-SUMIFS($N$2:$N$205,$A$2:$A$205,$A45,$B$2:$B$205,$B45,$C$2:$C$205,100))) | AE45: =IF(ISBLANK(O45),"",ABS(O45-SUMIFS($O$2:$O$205,$A$2:$A$205,$A45,$B$2:$B$205,$B45,$C$2:$C$205,100))) | AF45: =IF(ISBLANK(P45),"",ABS(P45-SUMIFS($P$2:$P$205,$A$2:$A$205,$A45,$B$2:$B$205,$B45,$C$2:$C$205,100))) | AG45: =IF(ISBLANK(Q45),"",ABS(Q45-SUMIFS($Q$2:$Q$205,$A$2:$A$205,$A45,$B$2:$B$205,$B45,$C$2:$C$205,100))) | AH45: =IF(ISBLANK(R45),"",ABS(R45-SUMIFS($R$2:$R$205,$A$2:$A$205,$A45,$B$2:$B$205,$B45,$C$2:$C$205,100))) | AI45: =IF(ISBLANK(S45),"",ABS(S45-SUMIFS($S$2:$S$205,$A$2:$A$205,$A45,$B$2:$B$205,$B45,$C$2:$C$205,100))) | AJ45: =MAX(V45:AI45) -> 0.070202189
A46: Ar | B46: Midpoint | C46: 30 | D46: -527.8844 | E46: -1.0738399 | F46: -114.4781 | G46: -11.154943 | H46: -8.7395896 | I46: -1.0991993 | J46: -0.58945879 | T46: =ABS(D46-SUMIFS($D$2:$D$205,$A$2:$A$205,$A46,$B$2:$B$205,$B46,$C$2:$C$205,100)) -> 7.1372597e-10 | U46: =ABS(E46-SUMIFS($E$2:$E$205,$A$2:$A$205,$A46,$B$2:$B$205,$B46,$C$2:$C$205,100)) -> 6.015564e-09 | V46: =IF(ISBLANK(F46),"",ABS(F46-SUMIFS($F$2:$F$205,$A$2:$A$205,$A46,$B$2:$B$205,$B46,$C$2:$C$205,100))) -> 0.00356591 | W46: =IF(ISBLANK(G46),"",ABS(G46-SUMIFS($G$2:$G$205,$A$2:$A$205,$A46,$B$2:$B$205,$B46,$C$2:$C$205,100))) -> 0.0035658273 | X46: =IF(ISBLANK(H46),"",ABS(H46-SUMIFS($H$2:$H$205,$A$2:$A$205,$A46,$B$2:$B$205,$B46,$C$2:$C$205,100))) -> 0.0035658387 | Y46: =IF(ISBLANK(I46),"",ABS(I46-SUMIFS($I$2:$I$205,$A$2:$A$205,$A46,$B$2:$B$205,$B46,$C$2:$C$205,100))) -> 0.003567248 | Z46: =IF(ISBLANK(J46),"",ABS(J46-SUMIFS($J$2:$J$205,$A$2:$A$205,$A46,$B$2:$B$205,$B46,$C$2:$C$205,100))) -> 0.0035671799 | AA46: =IF(ISBLANK(K46),"",ABS(K46-SUMIFS($K$2:$K$205,$A$2:$A$205,$A46,$B$2:$B$205,$B46,$C$2:$C$205,100))) | AB46: =IF(ISBLANK(L46),"",ABS(L46-SUMIFS($L$2:$L$205,$A$2:$A$205,$A46,$B$2:$B$205,$B46,$C$2:$C$205,100))) | AC46: =IF(ISBLANK(M46),"",ABS(M46-SUMIFS($M$2:$M$205,$A$2:$A$205,$A46,$B$2:$B$205,$B46,$C$2:$C$205,100))) | AD46: =IF(ISBLANK(N46),"",ABS(N46-SUMIFS($N$2:$N$205,$A$2:$A$205,$A46,$B$2:$B$205,$B46,$C$2:$C$205,100))) | AE46: =IF(ISBLANK(O46),"",ABS(O46-SUMIFS($O$2:$O$205,$A$2:$A$205,$A46,$B$2:$B$205,$B46,$C$2:$C$205,100))) | AF46: =IF(ISBLANK(P46),"",ABS(P46-SUMIFS($P$2:$P$205,$A$2:$A$205,$A46,$B$2:$B$205,$B46,$C$2:$C$205,100))) | AG46: =IF(ISBLANK(Q46),"",ABS(Q46-SUMIFS($Q$2:$Q$205,$A$2:$A$205,$A46,$B$2:$B$205,$B46,$C$2:$C$205,100))) | AH46: =IF(ISBLANK(R46),"",ABS(R46-SUMIFS($R$2:$R$205,$A$2:$A$205,$A46,$B$2:$B$205,$B46,$C$2:$C$205,100))) | AI46: =IF(ISBLANK(S46),"",ABS(S46-SUMIFS($S$2:$S$205,$A$2:$A$205,$A46,$B$2:$B$205,$B46,$C$2:$C$205,100))) | AJ46: =MAX(V46:AI46) -> 0.003567248
A47: Ar | B47: Midpoint | C47: 50 | D47: -527.8844 | E47: -1.0738399 | F47: -114.47454 | G47: -11.151379 | H47: -8.7360256 | I47: -1.095634 | J47: -0.58589352 | T47: =ABS(D47-SUMIFS($D$2:$D$205,$A$2:$A$205,$A47,$B$2:$B$205,$B47,$C$2:$C$205,100)) -> 2.1600499e-12 | U47: =ABS(E47-SUMIFS($E$2:$E$205,$A$2:$A$205,$A47,$B$2:$B$205,$B47,$C$2:$C$205,100)) -> 3.1479264e-12 | V47: =IF(ISBLANK(F47),"",ABS(F47-SUMIFS($F$2:$F$205,$A$2:$A$205,$A47,$B$2:$B$205,$B47,$C$2:$C$205,100))) -> 1.9088474e-06 | W47: =IF(ISBLANK(G47),"",ABS(G47-SUMIFS($G$2:$G$205,$A$2:$A$205,$A47,$B$2:$B$205,$B47,$C$2:$C$205,100))) -> 1.9088475e-06 | X47: =IF(ISBLANK(H47),"",ABS(H47-SUMIFS($H$2:$H$205,$A$2:$A$205,$A47,$B$2:$B$205,$B47,$C$2:$C$205,100))) -> 1.9083935e-06 | Y47: =IF(ISBLANK(I47),"",ABS(I47-SUMIFS($I$2:$I$205,$A$2:$A$205,$A47,$B$2:$B$205,$B47,$C$2:$C$205,100))) -> 1.9088475e-06 | Z47: =IF(ISBLANK(J47),"",ABS(J47-SUMIFS($J$2:$J$205,$A$2:$A$205,$A47,$B$2:$B$205,$B47,$C$2:$C$205,100))) -> 1.9089784e-06 | AA47: =IF(ISBLANK(K47),"",ABS(K47-SUMIFS($K$2:$K$205,$A$2:$A$205,$A47,$B$2:$B$205,$B47,$C$2:$C$205,100))) | AB47: =IF(ISBLANK(L47),"",ABS(L47-SUMIFS($L$2:$L$205,$A$2:$A$205,$A47,$B$2:$B$205,$B47,$C$2:$C$205,100))) | AC47: =IF(ISBLANK(M47),"",ABS(M47-SUMIFS($M$2:$M$205,$A$2:$A$205,$A47,$B$2:$B$205,$B47,$C$2:$C$205,100))) | AD47: =IF(ISBLANK(N47),"",ABS(N47-SUMIFS($N$2:$N$205,$A$2:$A$205,$A47,$B$2:$B$205,$B47,$C$2:$C$205,100))) | AE47: =IF(ISBLANK(O47),"",ABS(O47-SUMIFS($O$2:$O$205,$A$2:$A$205,$A47,$B$2:$B$205,$B47,$C$2:$C$205,100))) | AF47: =IF(ISBLANK(P47),"",ABS(P47-SUMIFS($P$2:$P$205,$A$2:$A$205,$A47,$B$2:$B$205,$B47,$C$2:$C$205,100))) | AG47: =IF(ISBLANK(Q47),"",ABS(Q47-SUMIFS($Q$2:$Q$205,$A$2:$A$205,$A47,$B$2:$B$205,$B47,$C$2:$C$205,100))) | AH47: =IF(ISBLANK(R47),"",ABS(R47-SUMIFS($R$2:$R$205,$A$2:$A$205,$A47,$B$2:$B$205,$B47,$C$2:$C$205,100))) | AI47: =IF(ISBLANK(S47),"",ABS(S47-SUMIFS($S$2:$S$205,$A$2:$A$205,$A47,$B$2:$B$205,$B47,$C$2:$C$205,100))) | AJ47: =MAX(V47:AI47) -> 1.9089784e-06
A48: Ar | B48: Midpoint | C48: 80 | D48: -527.8844 | E48: -1.0738399 | F48: -114.47453 | G48: -11.151377 | H48: -8.7360237 | I48: -1.0956321 | J48: -0.58589161 | T48: =ABS(D48-SUMIFS($D$2:$D$205,$A$2:$A$205,$A48,$B$2:$B$205,$B48,$C$2:$C$205,100)) -> 0 | U48: =ABS(E48-SUMIFS($E$2:$E$205,$A$2:$A$205,$A48,$B$2:$B$205,$B48,$C$2:$C$205,100)) -> 9.7033492e-14 | V48: =IF(ISBLANK(F48),"",ABS(F48-SUMIFS($F$2:$F$205,$A$2:$A$205,$A48,$B$2:$B$205,$B48,$C$2:$C$205,100))) -> 9.8793862e-11 | W48: =IF(ISBLANK(G48),"",ABS(G48-SUMIFS($G$2:$G$205,$A$2:$A$205,$A48,$B$2:$B$205,$B48,$C$2:$C$205,100))) -> 9.8889785e-11 | X48: =IF(ISBLANK(H48),"",ABS(H48-SUMIFS($H$2:$H$205,$A$2:$A$205,$A48,$B$2:$B$205,$B48,$C$2:$C$205,100))) -> 0 | Y48: =IF(ISBLANK(I48),"",ABS(I48-SUMIFS($I$2:$I$205,$A$2:$A$205,$A48,$B$2:$B$205,$B48,$C$2:$C$205,100))) -> 1.891749e-10 | Z48: =IF(ISBLANK(J48),"",ABS(J48-SUMIFS($J$2:$J$205,$A$2:$A$205,$A48,$B$2:$B$205,$B48,$C$2:$C$205,100))) -> 0 | AA48: =IF(ISBLANK(K48),"",ABS(K48-SUMIFS($K$2:$K$205,$A$2:$A$205,$A48,$B$2:$B$205,$B48,$C$2:$C$205,100))) | AB48: =IF(ISBLANK(L48),"",ABS(L48-SUMIFS($L$2:$L$205,$A$2:$A$205,$A48,$B$2:$B$205,$B48,$C$2:$C$205,100))) | AC48: =IF(ISBLANK(M48),"",ABS(M48-SUMIFS($M$2:$M$205,$A$2:$A$205,$A48,$B$2:$B$205,$B48,$C$2:$C$205,100))) | AD48: =IF(ISBLANK(N48),"",ABS(N48-SUMIFS($N$2:$N$205,$A$2:$A$205,$A48,$B$2:$B$205,$B48,$C$2:$C$205,100))) | AE48: =IF(ISBLANK(O48),"",ABS(O48-SUMIFS($O$2:$O$205,$A$2:$A$205,$A48,$B$2:$B$205,$B48,$C$2:$C$205,100))) | AF48: =IF(ISBLANK(P48),"",ABS(P48-SUMIFS($P$2:$P$205,$A$2:$A$205,$A48,$B$2:$B$205,$B48,$C$2:$C$205,100))) | AG48: =IF(ISBLANK(Q48),"",ABS(Q48-SUMIFS($Q$2:$Q$205,$A$2:$A$205,$A48,$B$2:$B$205,$B48,$C$2:$C$205,100))) | AH48: =IF(ISBLANK(R48),"",ABS(R48-SUMIFS($R$2:$R$205,$A$2:$A$205,$A48,$B$2:$B$205,$B48,$C$2:$C$205,100))) | AI48: =IF(ISBLANK(S48),"",ABS(S48-SUMIFS($S$2:$S$205,$A$2:$A$205,$A48,$B$2:$B$205,$B48,$C$2:$C$205,100))) | AJ48: =MAX(V48:AI48) -> 1.891749e-10
A49: Ar | B49: Midpoint | C49: 100 | D49: -527.8844 | E49: -1.0738399 | F49: -114.47453 | G49: -11.151377 | H49: -8.7360237 | I49: -1.0956321 | J49: -0.58589161 | T49: =ABS(D49-SUMIFS($D$2:$D$205,$A$2:$A$205,$A49,$B$2:$B$205,$B49,$C$2:$C$205,100)) -> 0 | U49: =ABS(E49-SUMIFS($E$2:$E$205,$A$2:$A$205,$A49,$B$2:$B$205,$B49,$C$2:$C$205,100)) -> 0 | V49: =IF(ISBLANK(F49),"",ABS(F49-SUMIFS($F$2:$F$205,$A$2:$A$205,$A49,$B$2:$B$205,$B49,$C$2:$C$205,100))) -> 0 | W49: =IF(ISBLANK(G49),"",ABS(G49-SUMIFS($G$2:$G$205,$A$2:$A$205,$A49,$B$2:$B$205,$B49,$C$2:$C$205,100))) -> 0 | X49: =IF(ISBLANK(H49),"",ABS(H49-SUMIFS($H$2:$H$205,$A$2:$A$205,$A49,$B$2:$B$205,$B49,$C$2:$C$205,100))) -> 0 | Y49: =IF(ISBLANK(I49),"",ABS(I49-SUMIFS($I$2:$I$205,$A$2:$A$205,$A49,$B$2:$B$205,$B49,$C$2:$C$205,100))) -> 0 | Z49: =IF(ISBLANK(J49),"",ABS(J49-SUMIFS($J$2:$J$205,$A$2:$A$205,$A49,$B$2:$B$205,$B49,$C$2:$C$205,100))) -> 0 | AA49: =IF(ISBLANK(K49),"",ABS(K49-SUMIFS($K$2:$K$205,$A$2:$A$205,$A49,$B$2:$B$205,$B49,$C$2:$C$205,100))) | AB49: =IF(ISBLANK(L49),"",ABS(L49-SUMIFS($L$2:$L$205,$A$2:$A$205,$A49,$B$2:$B$205,$B49,$C$2:$C$205,100))) | AC49: =IF(ISBLANK(M49),"",ABS(M49-SUMIFS($M$2:$M$205,$A$2:$A$205,$A49,$B$2:$B$205,$B49,$C$2:$C$205,100))) | AD49: =IF(ISBLANK(N49),"",ABS(N49-SUMIFS($N$2:$N$205,$A$2:$A$205,$A49,$B$2:$B$205,$B49,$C$2:$C$205,100))) | AE49: =IF(ISBLANK(O49),"",ABS(O49-SUMIFS($O$2:$O$205,$A$2:$A$205,$A49,$B$2:$B$205,$B49,$C$2:$C$205,100))) | AF49: =IF(ISBLANK(P49),"",ABS(P49-SUMIFS($P$2:$P$205,$A$2:$A$205,$A49,$B$2:$B$205,$B49,$C$2:$C$205,100))) | AG49: =IF(ISBLANK(Q49),"",ABS(Q49-SUMIFS($Q$2:$Q$205,$A$2:$A$205,$A49,$B$2:$B$205,$B49,$C$2:$C$205,100))) | AH49: =IF(ISBLANK(R49),"",ABS(R49-SUMIFS($R$2:$R$205,$A$2:$A$205,$A49,$B$2:$B$205,$B49,$C$2:$C$205,100))) | AI49: =IF(ISBLANK(S49),"",ABS(S49-SUMIFS($S$2:$S$205,$A$2:$A$205,$A49,$B$2:$B$205,$B49,$C$2:$C$205,100))) | AJ49: =MAX(V49:AI49) -> 0
A50: Ar | B50: Midpoint | C50: 150 | D50: -527.8844 | E50: -1.0738399 | F50: -114.47453 | G50: -11.151377 | H50: -8.7360237 | I50: -1.0956321 | J50: -0.58589161 | T50: =ABS(D50-SUMIFS($D$2:$D$205,$A$2:$A$205,$A50,$B$2:$B$205,$B50,$C$2:$C$205,100)) -> 0 | U50: =ABS(E50-SUMIFS($E$2:$E$205,$A$2:$A$205,$A50,$B$2:$B$205,$B50,$C$2:$C$205,100)) -> 1.6608936e-13 | V50: =IF(ISBLANK(F50),"",ABS(F50-SUMIFS($F$2:$F$205,$A$2:$A$205,$A50,$B$2:$B$205,$B50,$C$2:$C$205,100))) -> 1.2158807e-10 | W50: =IF(ISBLANK(G50),"",ABS(G50-SUMIFS($G$2:$G$205,$A$2:$A$205,$A50,$B$2:$B$205,$B50,$C$2:$C$205,100))) -> 1.2163959e-10 | X50: =IF(ISBLANK(H50),"",ABS(H50-SUMIFS($H$2:$H$205,$A$2:$A$205,$A50,$B$2:$B$205,$B50,$C$2:$C$205,100))) -> 0 | Y50: =IF(ISBLANK(I50),"",ABS(I50-SUMIFS($I$2:$I$205,$A$2:$A$205,$A50,$B$2:$B$205,$B50,$C$2:$C$205,100))) -> 1.6642487e-10 | Z50: =IF(ISBLANK(J50),"",ABS(J50-SUMIFS($J$2:$J$205,$A$2:$A$205,$A50,$B$2:$B$205,$B50,$C$2:$C$205,100))) -> 0 | AA50: =IF(ISBLANK(K50),"",ABS(K50-SUMIFS($K$2:$K$205,$A$2:$A$205,$A50,$B$2:$B$205,$B50,$C$2:$C$205,100))) | AB50: =IF(ISBLANK(L50),"",ABS(L50-SUMIFS($L$2:$L$205,$A$2:$A$205,$A50,$B$2:$B$205,$B50,$C$2:$C$205,100))) | AC50: =IF(ISBLANK(M50),"",ABS(M50-SUMIFS($M$2:$M$205,$A$2:$A$205,$A50,$B$2:$B$205,$B50,$C$2:$C$205,100))) | AD50: =IF(ISBLANK(N50),"",ABS(N50-SUMIFS($N$2:$N$205,$A$2:$A$205,$A50,$B$2:$B$205,$B50,$C$2:$C$205,100))) | AE50: =IF(ISBLANK(O50),"",ABS(O50-SUMIFS($O$2:$O$205,$A$2:$A$205,$A50,$B$2:$B$205,$B50,$C$2:$C$205,100))) | AF50: =IF(ISBLANK(P50),"",ABS(P50-SUMIFS($P$2:$P$205,$A$2:$A$205,$A50,$B$2:$B$205,$B50,$C$2:$C$205,100))) | AG50: =IF(ISBLANK(Q50),"",ABS(Q50-SUMIFS($Q$2:$Q$205,$A$2:$A$205,$A50,$B$2:$B$205,$B50,$C$2:$C$205,100))) | AH50: =IF(ISBLANK(R50),"",ABS(R50-SUMIFS($R$2:$R$205,$A$2:$A$205,$A50,$B$2:$B$205,$B50,$C$2:$C$205,100))) | AI50: =IF(ISBLANK(S50),"",ABS(S50-SUMIFS($S$2:$S$205,$A$2:$A$205,$A50,$B$2:$B$205,$B50,$C$2:$C$205,100))) | AJ50: =MAX(V50:AI50) -> 1.6642487e-10
A51: Ar | B51: Trapezoidal | C51: 5 | D51: -527.95785 | E51: -1.1511548 | F51: -114.14626 | G51: -10.861347 | H51: -8.4454486 | I51: -0.69076477 | J51: -0.18323986 | T51: =ABS(D51-SUMIFS($D$2:$D$205,$A$2:$A$205,$A51,$B$2:$B$205,$B51,$C$2:$C$205,100)) -> 0.073449954 | U51: =ABS(E51-SUMIFS($E$2:$E$205,$A$2:$A$205,$A51,$B$2:$B$205,$B51,$C$2:$C$205,100)) -> 0.077314919 | V51: =IF(ISBLANK(F51),"",ABS(F51-SUMIFS($F$2:$F$205,$A$2:$A$205,$A51,$B$2:$B$205,$B51,$C$2:$C$205,100))) -> 0.3282789 | W51: =IF(ISBLANK(G51),"",ABS(G51-SUMIFS($G$2:$G$205,$A$2:$A$205,$A51,$B$2:$B$205,$B51,$C$2:$C$205,100))) -> 0.2900298 | X51: =IF(ISBLANK(H51),"",ABS(H51-SUMIFS($H$2:$H$205,$A$2:$A$205,$A51,$B$2:$B$205,$B51,$C$2:$C$205,100))) -> 0.29057512 | Y51: =IF(ISBLANK(I51),"",ABS(I51-SUMIFS($I$2:$I$205,$A$2:$A$205,$A51,$B$2:$B$205,$B51,$C$2:$C$205,100))) -> 0.40486731 | Z51: =IF(ISBLANK(J51),"",ABS(J51-SUMIFS($J$2:$J$205,$A$2:$A$205,$A51,$B$2:$B$205,$B51,$C$2:$C$205,100))) -> 0.40265175 | AA51: =IF(ISBLANK(K51),"",ABS(K51-SUMIFS($K$2:$K$205,$A$2:$A$205,$A51,$B$2:$B$205,$B51,$C$2:$C$205,100))) | AB51: =IF(ISBLANK(L51),"",ABS(L51-SUMIFS($L$2:$L$205,$A$2:$A$205,$A51,$B$2:$B$205,$B51,$C$2:$C$205,100))) | AC51: =IF(ISBLANK(M51),"",ABS(M51-SUMIFS($M$2:$M$205,$A$2:$A$205,$A51,$B$2:$B$205,$B51,$C$2:$C$205,100))) | AD51: =IF(ISBLANK(N51),"",ABS(N51-SUMIFS($N$2:$N$205,$A$2:$A$205,$A51,$B$2:$B$205,$B51,$C$2:$C$205,100))) | AE51: =IF(ISBLANK(O51),"",ABS(O51-SUMIFS($O$2:$O$205,$A$2:$A$205,$A51,$B$2:$B$205,$B51,$C$2:$C$205,100))) | AF51: =IF(ISBLANK(P51),"",ABS(P51-SUMIFS($P$2:$P$205,$A$2:$A$205,$A51,$B$2:$B$205,$B51,$C$2:$C$205,100))) | AG51: =IF(ISBLANK(Q51),"",ABS(Q51-SUMIFS($Q$2:$Q$205,$A$2:$A$205,$A51,$B$2:$B$205,$B51,$C$2:$C$205,100))) | AH51: =IF(ISBLANK(R51),"",ABS(R51-SUMIFS($R$2:$R$205,$A$2:$A$205,$A51,$B$2:$B$205,$B51,$C$2:$C$205,100))) | AI51: =IF(ISBLANK(S51),"",ABS(S51-SUMIFS($S$2:$S$205,$A$2:$A$205,$A51,$B$2:$B$205,$B51,$C$2:$C$205,100))) | AJ51: =MAX(V51:AI51) -> 0.40486731
A52: Ar | B52: Trapezoidal | C52: 10 | D52: -527.88945 | E52: -1.078937 | F52: -114.2839 | G52: -10.957441 | H52: -8.5425585 | I52: -0.89172616 | J52: -0.38189351 | T52: =ABS(D52-SUMIFS($D$2:$D$205,$A$2:$A$205,$A52,$B$2:$B$205,$B52,$C$2:$C$205,100)) -> 0.0050447721 | U52: =ABS(E52-SUMIFS($E$2:$E$205,$A$2:$A$205,$A52,$B$2:$B$205,$B52,$C$2:$C$205,100)) -> 0.0050970908 | V52: =IF(ISBLANK(F52),"",ABS(F52-SUMIFS($F$2:$F$205,$A$2:$A$205,$A52,$B$2:$B$205,$B52,$C$2:$C$205,100))) -> 0.19063547 | W52: =IF(ISBLANK(G52),"",ABS(G52-SUMIFS($G$2:$G$205,$A$2:$A$205,$A52,$B$2:$B$205,$B52,$C$2:$C$205,100))) -> 0.19393667 | X52: =IF(ISBLANK(H52),"",ABS(H52-SUMIFS($H$2:$H$205,$A$2:$A$205,$A52,$B$2:$B$205,$B52,$C$2:$C$205,100))) -> 0.19346523 | Y52: =IF(ISBLANK(I52),"",ABS(I52-SUMIFS($I$2:$I$205,$A$2:$A$205,$A52,$B$2:$B$205,$B52,$C$2:$C$205,100))) -> 0.20390592 | Z52: =IF(ISBLANK(J52),"",ABS(J52-SUMIFS($J$2:$J$205,$A$2:$A$205,$A52,$B$2:$B$205,$B52,$C$2:$C$205,100))) -> 0.20399811 | AA52: =IF(ISBLANK(K52),"",ABS(K52-SUMIFS($K$2:$K$205,$A$2:$A$205,$A52,$B$2:$B$205,$B52,$C$2:$C$205,100))) | AB52: =IF(ISBLANK(L52),"",ABS(L52-SUMIFS($L$2:$L$205,$A$2:$A$205,$A52,$B$2:$B$205,$B52,$C$2:$C$205,100))) | AC52: =IF(ISBLANK(M52),"",ABS(M52-SUMIFS($M$2:$M$205,$A$2:$A$205,$A52,$B$2:$B$205,$B52,$C$2:$C$205,100))) | AD52: =IF(ISBLANK(N52),"",ABS(N52-SUMIFS($N$2:$N$205,$A$2:$A$205,$A52,$B$2:$B$205,$B52,$C$2:$C$205,100))) | AE52: =IF(ISBLANK(O52),"",ABS(O52-SUMIFS($O$2:$O$205,$A$2:$A$205,$A52,$B$2:$B$205,$B52,$C$2:$C$205,100))) | AF52: =IF(ISBLANK(P52),"",ABS(P52-SUMIFS($P$2:$P$205,$A$2:$A$205,$A52,$B$2:$B$205,$B52,$C$2:$C$205,100))) | AG52: =IF(ISBLANK(Q52),"",ABS(Q52-SUMIFS($Q$2:$Q$205,$A$2:$A$205,$A52,$B$2:$B$205,$B52,$C$2:$C$205,100))) | AH52: =IF(ISBLANK(R52),"",ABS(R52-SUMIFS($R$2:$R$205,$A$2:$A$205,$A52,$B$2:$B$205,$B52,$C$2:$C$205,100))) | AI52: =IF(ISBLANK(S52),"",ABS(S52-SUMIFS($S$2:$S$205,$A$2:$A$205,$A52,$B$2:$B$205,$B52,$C$2:$C$205,100))) | AJ52: =MAX(V52:AI52) -> 0.20399811
A53: Ar | B53: Trapezoidal | C53: 15 | D53: -527.88479 | E53: -1.0742536 | F53: -114.35909 | G53: -11.036268 | H53: -8.6210898 | I53: -0.97873786 | J53: -0.46891578 | T53: =ABS(D53-SUMIFS($D$2:$D$205,$A$2:$A$205,$A53,$B$2:$B$205,$B53,$C$2:$C$205,100)) -> 0.00038222642 | U53: =ABS(E53-SUMIFS($E$2:$E$205,$A$2:$A$205,$A53,$B$2:$B$205,$B53,$C$2:$C$205,100)) -> 0.00041370309 | V53: =IF(ISBLANK(F53),"",ABS(F53-SUMIFS($F$2:$F$205,$A$2:$A$205,$A53,$B$2:$B$205,$B53,$C$2:$C$205,100))) -> 0.11544335 | W53: =IF(ISBLANK(G53),"",ABS(G53-SUMIFS($G$2:$G$205,$A$2:$A$205,$A53,$B$2:$B$205,$B53,$C$2:$C$205,100))) -> 0.11510876 | X53: =IF(ISBLANK(H53),"",ABS(H53-SUMIFS($H$2:$H$205,$A$2:$A$205,$A53,$B$2:$B$205,$B53,$C$2:$C$205,100))) -> 0.11493388 | Y53: =IF(ISBLANK(I53),"",ABS(I53-SUMIFS($I$2:$I$205,$A$2:$A$205,$A53,$B$2:$B$205,$B53,$C$2:$C$205,100))) -> 0.11689422 | Z53: =IF(ISBLANK(J53),"",ABS(J53-SUMIFS($J$2:$J$205,$A$2:$A$205,$A53,$B$2:$B$205,$B53,$C$2:$C$205,100))) -> 0.11697583 | AA53: =IF(ISBLANK(K53),"",ABS(K53-SUMIFS($K$2:$K$205,$A$2:$A$205,$A53,$B$2:$B$205,$B53,$C$2:$C$205,100))) | AB53: =IF(ISBLANK(L53),"",ABS(L53-SUMIFS($L$2:$L$205,$A$2:$A$205,$A53,$B$2:$B$205,$B53,$C$2:$C$205,100))) | AC53: =IF(ISBLANK(M53),"",ABS(M53-SUMIFS($M$2:$M$205,$A$2:$A$205,$A53,$B$2:$B$205,$B53,$C$2:$C$205,100))) | AD53: =IF(ISBLANK(N53),"",ABS(N53-SUMIFS($N$2:$N$205,$A$2:$A$205,$A53,$B$2:$B$205,$B53,$C$2:$C$205,100))) | AE53: =IF(ISBLANK(O53),"",ABS(O53-SUMIFS($O$2:$O$205,$A$2:$A$205,$A53,$B$2:$B$205,$B53,$C$2:$C$205,100))) | AF53: =IF(ISBLANK(P53),"",ABS(P53-SUMIFS($P$2:$P$205,$A$2:$A$205,$A53,$B$2:$B$205,$B53,$C$2:$C$205,100))) | AG53: =IF(ISBLANK(Q53),"",ABS(Q53-SUMIFS($Q$2:$Q$205,$A$2:$A$205,$A53,$B$2:$B$205,$B53,$C$2:$C$205,100))) | AH53: =IF(ISBLANK(R53),"",ABS(R53-SUMIFS($R$2:$R$205,$A$2:$A$205,$A53,$B$2:$B$205,$B53,$C$2:$C$205,100))) | AI53: =IF(ISBLANK(S53),"",ABS(S53-SUMIFS($S$2:$S$205,$A$2:$A$205,$A53,$B$2:$B$205,$B53,$C$2:$C$205,100))) | AJ53: =MAX(V53:AI53) -> 0.11697583
... A82: Ar | B82: Algebraic | C82: 100 | D82: -527.88445 | E82: -1.0738831 | F82: -114.47457 | G82: -11.15138 | H82: -8.7360231 | I82: -1.0956324 | J82: -0.58589156 | T82: =ABS(D82-SUMIFS($D$2:$D$205,$A$2:$A$205,$A82,$B$2:$B$205,$B82,$C$2:$C$205,100)) -> 0 | U82: =ABS(E82-SUMIFS($E$2:$E$205,$A$2:$A$205,$A82,$B$2:$B$205,$B82,$C$2:$C$205,100)) -> 0 | V82: =IF(ISBLANK(F82),"",ABS(F82-SUMIFS($F$2:$F$205,$A$2:$A$205,$A82,$B$2:$B$205,$B82,$C$2:$C$205,100))) -> 0 | W82: =IF(ISBLANK(G82),"",ABS(G82-SUMIFS($G$2:$G$205,$A$2:$A$205,$A82,$B$2:$B$205,$B82,$C$2:$C$205,100))) -> 0 | X82: =IF(ISBLANK(H82),"",ABS(H82-SUMIFS($H$2:$H$205,$A$2:$A$205,$A82,$B$2:$B$205,$B82,$C$2:$C$205,100))) -> 0 | Y82: =IF(ISBLANK(I82),"",ABS(I82-SUMIFS($I$2:$I$205,$A$2:$A$205,$A82,$B$2:$B$205,$B82,$C$2:$C$205,100))) -> 0 | Z82: =IF(ISBLANK(J82),"",ABS(J82-SUMIFS($J$2:$J$205,$A$2:$A$205,$A82,$B$2:$B$205,$B82,$C$2:$C$205,100))) -> 0 | AA82: =IF(ISBLANK(K82),"",ABS(K82-SUMIFS($K$2:$K$205,$A$2:$A$205,$A82,$B$2:$B$205,$B82,$C$2:$C$205,100))) | AB82: =IF(ISBLANK(L82),"",ABS(L82-SUMIFS($L$2:$L$205,$A$2:$A$205,$A82,$B$2:$B$205,$B82,$C$2:$C$205,100))) | AC82: =IF(ISBLANK(M82),"",ABS(M82-SUMIFS($M$2:$M$205,$A$2:$A$205,$A82,$B$2:$B$205,$B82,$C$2:$C$205,100))) | AD82: =IF(ISBLANK(N82),"",ABS(N82-SUMIFS($N$2:$N$205,$A$2:$A$205,$A82,$B$2:$B$205,$B82,$C$2:$C$205,100))) | AE82: =IF(ISBLANK(O82),"",ABS(O82-SUMIFS($O$2:$O$205,$A$2:$A$205,$A82,$B$2:$B$205,$B82,$C$2:$C$205,100))) | AF82: =IF(ISBLANK(P82),"",ABS(P82-SUMIFS($P$2:$P$205,$A$2:$A$205,$A82,$B$2:$B$205,$B82,$C$2:$C$205,100))) | AG82: =IF(ISBLANK(Q82),"",ABS(Q82-SUMIFS($Q$2:$Q$205,$A$2:$A$205,$A82,$B$2:$B$205,$B82,$C$2:$C$205,100))) | AH82: =IF(ISBLANK(R82),"",ABS(R82-SUMIFS($R$2:$R$205,$A$2:$A$205,$A82,$B$2:$B$205,$B82,$C$2:$C$205,100))) | AI82: =IF(ISBLANK(S82),"",ABS(S82-SUMIFS($S$2:$S$205,$A$2:$A$205,$A82,$B$2:$B$205,$B82,$C$2:$C$205,100))) | AJ82: =MAX(V82:AI82) -> 0
A83: Zn | B83: Midpoint | C83: 5 | D83: -1779.9332 | E83: -2.1482776 | F83: -345.8446 | G83: -41.844811 | H83: -36.864802 | I83: -4.7408032 | J83: -3.1611938 | K83: -0.52541526 | L83: -0.35575859 | T83: =ABS(D83-SUMIFS($D$2:$D$205,$A$2:$A$205,$A83,$B$2:$B$205,$B83,$C$2:$C$205,100)) -> 0.043851586 | U83: =ABS(E83-SUMIFS($E$2:$E$205,$A$2:$A$205,$A83,$B$2:$B$205,$B83,$C$2:$C$205,100)) -> 0.010647553 | V83: =IF(ISBLANK(F83),"",ABS(F83-SUMIFS($F$2:$F$205,$A$2:$A$205,$A83,$B$2:$B$205,$B83,$C$2:$C$205,100))) -> 0.0068973331 | W83: =IF(ISBLANK(G83),"",ABS(G83-SUMIFS($G$2:$G$205,$A$2:$A$205,$A83,$B$2:$B$205,$B83,$C$2:$C$205,100))) -> 0.041714556 | X83: =IF(ISBLANK(H83),"",ABS(H83-SUMIFS($H$2:$H$205,$A$2:$A$205,$A83,$B$2:$B$205,$B83,$C$2:$C$205,100))) -> 0.034183631 | Y83: =IF(ISBLANK(I83),"",ABS(I83-SUMIFS($I$2:$I$205,$A$2:$A$205,$A83,$B$2:$B$205,$B83,$C$2:$C$205,100))) -> 0.034083336 | Z83: =IF(ISBLANK(J83),"",ABS(J83-SUMIFS($J$2:$J$205,$A$2:$A$205,$A83,$B$2:$B$205,$B83,$C$2:$C$205,100))) -> 0.03422045 | AA83: =IF(ISBLANK(K83),"",ABS(K83-SUMIFS($K$2:$K$205,$A$2:$A$205,$A83,$B$2:$B$205,$B83,$C$2:$C$205,100))) -> 0.020258848 | AB83: =IF(ISBLANK(L83),"",ABS(L83-SUMIFS($L$2:$L$205,$A$2:$A$205,$A83,$B$2:$B$205,$B83,$C$2:$C$205,100))) -> 0.0038058771 | AC83: =IF(ISBLANK(M83),"",ABS(M83-SUMIFS($M$2:$M$205,$A$2:$A$205,$A83,$B$2:$B$205,$B83,$C$2:$C$205,100))) | AD83: =IF(ISBLANK(N83),"",ABS(N83-SUMIFS($N$2:$N$205,$A$2:$A$205,$A83,$B$2:$B$205,$B83,$C$2:$C$205,100))) | AE83: =IF(ISBLANK(O83),"",ABS(O83-SUMIFS($O$2:$O$205,$A$2:$A$205,$A83,$B$2:$B$205,$B83,$C$2:$C$205,100))) | AF83: =IF(ISBLANK(P83),"",ABS(P83-SUMIFS($P$2:$P$205,$A$2:$A$205,$A83,$B$2:$B$205,$B83,$C$2:$C$205,100))) | AG83: =IF(ISBLANK(Q83),"",ABS(Q83-SUMIFS($Q$2:$Q$205,$A$2:$A$205,$A83,$B$2:$B$205,$B83,$C$2:$C$205,100))) | AH83: =IF(ISBLANK(R83),"",ABS(R83-SUMIFS($R$2:$R$205,$A$2:$A$205,$A83,$B$2:$B$205,$B83,$C$2:$C$205,100))) | AI83: =IF(ISBLANK(S83),"",ABS(S83-SUMIFS($S$2:$S$205,$A$2:$A$205,$A83,$B$2:$B$205,$B83,$C$2:$C$205,100))) | AJ83: =MAX(V83:AI83) -> 0.041714556
A84: Zn | B84: Midpoint | C84: 10 | D84: -1779.9497 | E84: -2.1347499 | F84: -345.84591 | G84: -41.810802 | H84: -36.836243 | I84: -4.7794472 | J84: -3.2000479 | K84: -0.55198834 | L84: -0.35407491 | T84: =ABS(D84-SUMIFS($D$2:$D$205,$A$2:$A$205,$A84,$B$2:$B$205,$B84,$C$2:$C$205,100)) -> 0.02731301 | U84: =ABS(E84-SUMIFS($E$2:$E$205,$A$2:$A$205,$A84,$B$2:$B$205,$B84,$C$2:$C$205,100)) -> 0.024175339 | V84: =IF(ISBLANK(F84),"",ABS(F84-SUMIFS($F$2:$F$205,$A$2:$A$205,$A84,$B$2:$B$205,$B84,$C$2:$C$205,100))) -> 0.0082075284 | W84: =IF(ISBLANK(G84),"",ABS(G84-SUMIFS($G$2:$G$205,$A$2:$A$205,$A84,$B$2:$B$205,$B84,$C$2:$C$205,100))) -> 0.0077063127 | X84: =IF(ISBLANK(H84),"",ABS(H84-SUMIFS($H$2:$H$205,$A$2:$A$205,$A84,$B$2:$B$205,$B84,$C$2:$C$205,100))) -> 0.0056237454 | Y84: =IF(ISBLANK(I84),"",ABS(I84-SUMIFS($I$2:$I$205,$A$2:$A$205,$A84,$B$2:$B$205,$B84,$C$2:$C$205,100))) -> 0.0045606826 | Z84: =IF(ISBLANK(J84),"",ABS(J84-SUMIFS($J$2:$J$205,$A$2:$A$205,$A84,$B$2:$B$205,$B84,$C$2:$C$205,100))) -> 0.0046336323 | AA84: =IF(ISBLANK(K84),"",ABS(K84-SUMIFS($K$2:$K$205,$A$2:$A$205,$A84,$B$2:$B$205,$B84,$C$2:$C$205,100))) -> 0.006314229 | AB84: =IF(ISBLANK(L84),"",ABS(L84-SUMIFS($L$2:$L$205,$A$2:$A$205,$A84,$B$2:$B$205,$B84,$C$2:$C$205,100))) -> 0.0021221944 | AC84: =IF(ISBLANK(M84),"",ABS(M84-SUMIFS($M$2:$M$205,$A$2:$A$205,$A84,$B$2:$B$205,$B84,$C$2:$C$205,100))) | AD84: =IF(ISBLANK(N84),"",ABS(N84-SUMIFS($N$2:$N$205,$A$2:$A$205,$A84,$B$2:$B$205,$B84,$C$2:$C$205,100))) | AE84: =IF(ISBLANK(O84),"",ABS(O84-SUMIFS($O$2:$O$205,$A$2:$A$205,$A84,$B$2:$B$205,$B84,$C$2:$C$205,100))) | AF84: =IF(ISBLANK(P84),"",ABS(P84-SUMIFS($P$2:$P$205,$A$2:$A$205,$A84,$B$2:$B$205,$B84,$C$2:$C$205,100))) | AG84: =IF(ISBLANK(Q84),"",ABS(Q84-SUMIFS($Q$2:$Q$205,$A$2:$A$205,$A84,$B$2:$B$205,$B84,$C$2:$C$205,100))) | AH84: =IF(ISBLANK(R84),"",ABS(R84-SUMIFS($R$2:$R$205,$A$2:$A$205,$A84,$B$2:$B$205,$B84,$C$2:$C$205,100))) | AI84: =IF(ISBLANK(S84),"",ABS(S84-SUMIFS($S$2:$S$205,$A$2:$A$205,$A84,$B$2:$B$205,$B84,$C$2:$C$205,100))) | AJ84: =MAX(V84:AI84) -> 0.0082075284
A85: Zn | B85: Midpoint | C85: 15 | D85: -1779.9769 | E85: -2.1600354 | F85: -345.85782 | G85: -41.823235 | H85: -36.850378 | I85: -4.7936996 | J85: -3.2141739 | K85: -0.5646798 | L85: -0.37071778 | T85: =ABS(D85-SUMIFS($D$2:$D$205,$A$2:$A$205,$A85,$B$2:$B$205,$B85,$C$2:$C$205,100)) -> 8.7646675e-05 | U85: =ABS(E85-SUMIFS($E$2:$E$205,$A$2:$A$205,$A85,$B$2:$B$205,$B85,$C$2:$C$205,100)) -> 0.0011101622 | V85: =IF(ISBLANK(F85),"",ABS(F85-SUMIFS($F$2:$F$205,$A$2:$A$205,$A85,$B$2:$B$205,$B85,$C$2:$C$205,100))) -> 0.020111983 | W85: =IF(ISBLANK(G85),"",ABS(G85-SUMIFS($G$2:$G$205,$A$2:$A$205,$A85,$B$2:$B$205,$B85,$C$2:$C$205,100))) -> 0.0201387 | X85: =IF(ISBLANK(H85),"",ABS(H85-SUMIFS($H$2:$H$205,$A$2:$A$205,$A85,$B$2:$B$205,$B85,$C$2:$C$205,100))) -> 0.019759234 | Y85: =IF(ISBLANK(I85),"",ABS(I85-SUMIFS($I$2:$I$205,$A$2:$A$205,$A85,$B$2:$B$205,$B85,$C$2:$C$205,100))) -> 0.018813091 | Z85: =IF(ISBLANK(J85),"",ABS(J85-SUMIFS($J$2:$J$205,$A$2:$A$205,$A85,$B$2:$B$205,$B85,$C$2:$C$205,100))) -> 0.018759598 | AA85: =IF(ISBLANK(K85),"",ABS(K85-SUMIFS($K$2:$K$205,$A$2:$A$205,$A85,$B$2:$B$205,$B85,$C$2:$C$205,100))) -> 0.019005688 | AB85: =IF(ISBLANK(L85),"",ABS(L85-SUMIFS($L$2:$L$205,$A$2:$A$205,$A85,$B$2:$B$205,$B85,$C$2:$C$205,100))) -> 0.018765066 | AC85: =IF(ISBLANK(M85),"",ABS(M85-SUMIFS($M$2:$M$205,$A$2:$A$205,$A85,$B$2:$B$205,$B85,$C$2:$C$205,100))) | AD85: =IF(ISBLANK(N85),"",ABS(N85-SUMIFS($N$2:$N$205,$A$2:$A$205,$A85,$B$2:$B$205,$B85,$C$2:$C$205,100))) | AE85: =IF(ISBLANK(O85),"",ABS(O85-SUMIFS($O$2:$O$205,$A$2:$A$205,$A85,$B$2:$B$205,$B85,$C$2:$C$205,100))) | AF85: =IF(ISBLANK(P85),"",ABS(P85-SUMIFS($P$2:$P$205,$A$2:$A$205,$A85,$B$2:$B$205,$B85,$C$2:$C$205,100))) | AG85: =IF(ISBLANK(Q85),"",ABS(Q85-SUMIFS($Q$2:$Q$205,$A$2:$A$205,$A85,$B$2:$B$205,$B85,$C$2:$C$205,100))) | AH85: =IF(ISBLANK(R85),"",ABS(R85-SUMIFS($R$2:$R$205,$A$2:$A$205,$A85,$B$2:$B$205,$B85,$C$2:$C$205,100))) | AI85: =IF(ISBLANK(S85),"",ABS(S85-SUMIFS($S$2:$S$205,$A$2:$A$205,$A85,$B$2:$B$205,$B85,$C$2:$C$205,100))) | AJ85: =MAX(V85:AI85) -> 0.0201387
A86: Zn | B86: Midpoint | C86: 20 | D86: -1779.9769 | E86: -2.1590207 | F86: -345.85017 | G86: -41.815529 | H86: -36.842991 | I86: -4.7872805 | J86: -3.2078003 | K86: -0.55809349 | L86: -0.36430877 | T86: =ABS(D86-SUMIFS($D$2:$D$205,$A$2:$A$205,$A86,$B$2:$B$205,$B86,$C$2:$C$205,100)) -> 0.00012710423 | U86: =ABS(E86-SUMIFS($E$2:$E$205,$A$2:$A$205,$A86,$B$2:$B$205,$B86,$C$2:$C$205,100)) -> 9.5461966e-05 | V86: =IF(ISBLANK(F86),"",ABS(F86-SUMIFS($F$2:$F$205,$A$2:$A$205,$A86,$B$2:$B$205,$B86,$C$2:$C$205,100))) -> 0.012470238 | W86: =IF(ISBLANK(G86),"",ABS(G86-SUMIFS($G$2:$G$205,$A$2:$A$205,$A86,$B$2:$B$205,$B86,$C$2:$C$205,100))) -> 0.012432664 | X86: =IF(ISBLANK(H86),"",ABS(H86-SUMIFS($H$2:$H$205,$A$2:$A$205,$A86,$B$2:$B$205,$B86,$C$2:$C$205,100))) -> 0.012372282 | Y86: =IF(ISBLANK(I86),"",ABS(I86-SUMIFS($I$2:$I$205,$A$2:$A$205,$A86,$B$2:$B$205,$B86,$C$2:$C$205,100))) -> 0.012393916 | Z86: =IF(ISBLANK(J86),"",ABS(J86-SUMIFS($J$2:$J$205,$A$2:$A$205,$A86,$B$2:$B$205,$B86,$C$2:$C$205,100))) -> 0.012386026 | AA86: =IF(ISBLANK(K86),"",ABS(K86-SUMIFS($K$2:$K$205,$A$2:$A$205,$A86,$B$2:$B$205,$B86,$C$2:$C$205,100))) -> 0.01241938 | AB86: =IF(ISBLANK(L86),"",ABS(L86-SUMIFS($L$2:$L$205,$A$2:$A$205,$A86,$B$2:$B$205,$B86,$C$2:$C$205,100))) -> 0.012356058 | AC86: =IF(ISBLANK(M86),"",ABS(M86-SUMIFS($M$2:$M$205,$A$2:$A$205,$A86,$B$2:$B$205,$B86,$C$2:$C$205,100))) | AD86: =IF(ISBLANK(N86),"",ABS(N86-SUMIFS($N$2:$N$205,$A$2:$A$205,$A86,$B$2:$B$205,$B86,$C$2:$C$205,100))) | AE86: =IF(ISBLANK(O86),"",ABS(O86-SUMIFS($O$2:$O$205,$A$2:$A$205,$A86,$B$2:$B$205,$B86,$C$2:$C$205,100))) | AF86: =IF(ISBLANK(P86),"",ABS(P86-SUMIFS($P$2:$P$205,$A$2:$A$205,$A86,$B$2:$B$205,$B86,$C$2:$C$205,100))) | AG86: =IF(ISBLANK(Q86),"",ABS(Q86-SUMIFS($Q$2:$Q$205,$A$2:$A$205,$A86,$B$2:$B$205,$B86,$C$2:$C$205,100))) | AH86: =IF(ISBLANK(R86),"",ABS(R86-SUMIFS($R$2:$R$205,$A$2:$A$205,$A86,$B$2:$B$205,$B86,$C$2:$C$205,100))) | AI86: =IF(ISBLANK(S86),"",ABS(S86-SUMIFS($S$2:$S$205,$A$2:$A$205,$A86,$B$2:$B$205,$B86,$C$2:$C$205,100))) | AJ86: =MAX(V86:AI86) -> 0.012470238
